<mujoco model="panda">
    <compiler angle="radian" autolimits="true"/>

    <default>
      <default class="panda">
        <joint armature="0.1" damping="1" axis="0 0 1" range="-2.8973 2.8973"/>
        <default class="panda/visual">
          <geom type="mesh" contype="0" conaffinity="0" group="2"/>
        </default>
        <default class="panda/collision">
          <geom type="mesh" group="3"/>
        </default>
        <site size="0.001" rgba="0.5 0.5 0.5 0.3" group="4"/>
      </default>
    </default>

    <asset>
      <material name="white" rgba="1 1 1 1"/>
      <material name="off_white" rgba="0.901961 0.921569 0.929412 1"/>
      <material name="dark_grey" rgba="0.25 0.25 0.25 1"/>
      <material name="green" rgba="0 1 0 1"/>
      <material name="light_blue" rgba="0.039216 0.541176 0.780392 1"/>
      <material name="metal" rgba="0.58 0.58 0.58 1"/>
      <material name="silicone" rgba="0.1882 0.1882 0.1882 1"/>
      <material name="gray" rgba="0.4627 0.4627 0.4627 1"/>
      <material name="black" rgba="0.149 0.149 0.149 1"/>

      <mesh name="link0_c" file="franka_emika_panda/meshes/link0.stl"/>
      <mesh name="link1_c" file="franka_emika_panda/meshes/link1.stl"/>
      <mesh name="link2_c" file="franka_emika_panda/meshes/link2.stl"/>
      <mesh name="link3_c" file="franka_emika_panda/meshes/link3.stl"/>
      <mesh name="link4_c" file="franka_emika_panda/meshes/link4.stl"/>
      <mesh name="link5_c0" file="franka_emika_panda/meshes/link5_collision_0.obj"/>
      <mesh name="link5_c1" file="franka_emika_panda/meshes/link5_collision_1.obj"/>
      <mesh name="link5_c2" file="franka_emika_panda/meshes/link5_collision_2.obj"/>
      <mesh name="link6_c" file="franka_emika_panda/meshes/link6.stl"/>
      <mesh name="link7_c" file="franka_emika_panda/meshes/link7.stl"/>
      <mesh file="franka_emika_panda/meshes/link0_0.obj"/>
      <mesh file="franka_emika_panda/meshes/link0_1.obj"/>
      <mesh file="franka_emika_panda/meshes/link0_2.obj"/>
      <mesh file="franka_emika_panda/meshes/link0_3.obj"/>
      <mesh file="franka_emika_panda/meshes/link0_4.obj"/>
      <mesh file="franka_emika_panda/meshes/link0_5.obj"/>
      <mesh file="franka_emika_panda/meshes/link0_7.obj"/>
      <mesh file="franka_emika_panda/meshes/link0_8.obj"/>
      <mesh file="franka_emika_panda/meshes/link0_9.obj"/>
      <mesh file="franka_emika_panda/meshes/link0_10.obj"/>
      <mesh file="franka_emika_panda/meshes/link0_11.obj"/>
      <mesh file="franka_emika_panda/meshes/link1.obj"/>
      <mesh file="franka_emika_panda/meshes/link2.obj"/>
      <mesh file="franka_emika_panda/meshes/link3_0.obj"/>
      <mesh file="franka_emika_panda/meshes/link3_1.obj"/>
      <mesh file="franka_emika_panda/meshes/link3_2.obj"/>
      <mesh file="franka_emika_panda/meshes/link3_3.obj"/>
      <mesh file="franka_emika_panda/meshes/link4_0.obj"/>
      <mesh file="franka_emika_panda/meshes/link4_1.obj"/>
      <mesh file="franka_emika_panda/meshes/link4_2.obj"/>
      <mesh file="franka_emika_panda/meshes/link4_3.obj"/>
      <mesh file="franka_emika_panda/meshes/link5_0.obj"/>
      <mesh file="franka_emika_panda/meshes/link5_1.obj"/>
      <mesh file="franka_emika_panda/meshes/link5_2.obj"/>
      <mesh file="franka_emika_panda/meshes/link6_0.obj"/>
      <mesh file="franka_emika_panda/meshes/link6_1.obj"/>
      <mesh file="franka_emika_panda/meshes/link6_2.obj"/>
      <mesh file="franka_emika_panda/meshes/link6_3.obj"/>
      <mesh file="franka_emika_panda/meshes/link6_4.obj"/>
      <mesh file="franka_emika_panda/meshes/link6_5.obj"/>
      <mesh file="franka_emika_panda/meshes/link6_6.obj"/>
      <mesh file="franka_emika_panda/meshes/link6_7.obj"/>
      <mesh file="franka_emika_panda/meshes/link6_8.obj"/>
      <mesh file="franka_emika_panda/meshes/link6_9.obj"/>
      <mesh file="franka_emika_panda/meshes/link6_10.obj"/>
      <mesh file="franka_emika_panda/meshes/link6_11.obj"/>
      <mesh file="franka_emika_panda/meshes/link6_12.obj"/>
      <mesh file="franka_emika_panda/meshes/link6_13.obj"/>
      <mesh file="franka_emika_panda/meshes/link6_14.obj"/>
      <mesh file="franka_emika_panda/meshes/link6_15.obj"/>
      <mesh file="franka_emika_panda/meshes/link6_16.obj"/>
      <mesh file="franka_emika_panda/meshes/link7_0.obj"/>
      <mesh file="franka_emika_panda/meshes/link7_1.obj"/>
      <mesh file="franka_emika_panda/meshes/link7_2.obj"/>
      <mesh file="franka_emika_panda/meshes/link7_3.obj"/>
      <mesh file="franka_emika_panda/meshes/link7_4.obj"/>
      <mesh file="franka_emika_panda/meshes/link7_5.obj"/>
      <mesh file="franka_emika_panda/meshes/link7_6.obj"/>
      <mesh file="franka_emika_panda/meshes/link7_7.obj"/>

      <mesh name="fabase" file="botyard/meshes/fabase.STL"/>
      <mesh name="falink2" file="botyard/meshes/falink2.STL"/>
      <mesh name="falink1" file="botyard/meshes/falink1.STL"/>
      <mesh name="pmbase" file="botyard/meshes/pmbase.STL"/>
      <mesh name="palm" file="botyard/meshes/palm.STL"/>
      <mesh name="thbase" file="botyard/meshes/thbase.STL"/>
      <mesh name="thproximal" file="botyard/meshes/thproximal.STL"/>
      <mesh name="thmiddle" file="botyard/meshes/thmiddle.STL"/>
      <mesh name="thdistal" file="botyard/meshes/thdistal.STL"/>
      <mesh name="ffbase" file="botyard/meshes/ffbase.STL"/>
      <mesh name="ffproximal" file="botyard/meshes/ffproximal.STL"/>
      <mesh name="ffmiddle" file="botyard/meshes/ffmiddle.STL"/>
      <mesh name="ffdistal" file="botyard/meshes/ffdistal.STL"/>
      <mesh name="mfbase" file="botyard/meshes/mfbase.STL"/>
      <mesh name="mfproximal" file="botyard/meshes/mfproximal.STL"/>
      <mesh name="mfmiddle" file="botyard/meshes/mfmiddle.STL"/>
      <mesh name="mfdistal" file="botyard/meshes/mfdistal.STL"/>
      <mesh name="rfbase" file="botyard/meshes/rfbase.STL"/>
      <mesh name="rfproximal" file="botyard/meshes/rfproximal.STL"/>
      <mesh name="rfmiddle" file="botyard/meshes/rfmiddle.STL"/>
      <mesh name="rfdistal" file="botyard/meshes/rfdistal.STL"/>
      <mesh name="lfpalm" file="botyard/meshes/lfpalm.STL"/>
      <mesh name="lfbase" file="botyard/meshes/lfbase.STL"/>
      <mesh name="lfproximal" file="botyard/meshes/lfproximal.STL"/>
      <mesh name="lfmiddle" file="botyard/meshes/lfmiddle.STL"/>
      <mesh name="lfdistal" file="botyard/meshes/lfdistal.STL"/>
    </asset>

    <worldbody>
      <body name="link0" childclass="panda">
        <inertial mass="0.629769" pos="-0.041018 -0.00014 0.049974"
          fullinertia="0.00315 0.00388 0.004285 8.2904e-7 0.00015 8.2299e-6"/>
        <geom mesh="link0_0" material="off_white" class="panda/visual"/>
        <geom mesh="link0_1" material="dark_grey" class="panda/visual"/>
        <geom mesh="link0_2" material="off_white" class="panda/visual"/>
        <geom mesh="link0_3" material="dark_grey" class="panda/visual"/>
        <geom mesh="link0_4" material="off_white" class="panda/visual"/>
        <geom mesh="link0_5" material="dark_grey" class="panda/visual"/>
        <geom mesh="link0_7" material="white" class="panda/visual"/>
        <geom mesh="link0_8" material="white" class="panda/visual"/>
        <geom mesh="link0_9" material="dark_grey" class="panda/visual"/>
        <geom mesh="link0_10" material="off_white" class="panda/visual"/>
        <geom mesh="link0_11" material="white" class="panda/visual"/>
        <geom mesh="link0_c" class="panda/collision"/>
        <body name="link1" pos="0 0 0.333">
          <inertial mass="4.970684" pos="0.003875 0.002081 -0.04762"
            fullinertia="0.70337 0.70661 0.0091170 -0.00013900 0.0067720 0.019169"/>
          <joint name="joint1"/>
          <site name="joint1"/>
          <geom material="white" mesh="link1" class="panda/visual"/>
          <geom mesh="link1_c" class="panda/collision"/>
          <body name="link2" quat="1 -1 0 0">
            <inertial mass="0.646926" pos="-0.003141 -0.02872 0.003495"
              fullinertia="0.0079620 2.8110e-2 2.5995e-2 -3.925e-3 1.0254e-2 7.04e-4"/>
            <joint name="joint2" range="-1.7628 1.7628"/>
            <site name="joint2"/>
            <geom material="white" mesh="link2" class="panda/visual"/>
            <geom mesh="link2_c" class="panda/collision"/>
            <body name="link3" pos="0 -0.316 0" quat="1 1 0 0">
              <inertial mass="3.228604" pos="2.7518e-2 3.9252e-2 -6.6502e-2"
                fullinertia="3.7242e-2 3.6155e-2 1.083e-2 -4.761e-3 -1.1396e-2 -1.2805e-2"/>
              <joint name="joint3"/>
              <site name="joint3"/>
              <geom mesh="link3_0" material="white" class="panda/visual"/>
              <geom mesh="link3_1" material="white" class="panda/visual"/>
              <geom mesh="link3_2" material="white" class="panda/visual"/>
              <geom mesh="link3_3" material="dark_grey" class="panda/visual"/>
              <geom mesh="link3_c" class="panda/collision"/>
              <body name="link4" pos="0.0825 0 0" quat="1 1 0 0">
                <inertial mass="3.587895" pos="-5.317e-2 1.04419e-1 2.7454e-2"
                  fullinertia="2.5853e-2 1.9552e-2 2.8323e-2 7.796e-3 -1.332e-3 8.641e-3"/>
                <joint name="joint4" range="-3.0718 -0.0698"/>
                <site name="joint4"/>
                <geom mesh="link4_0" material="white" class="panda/visual"/>
                <geom mesh="link4_1" material="white" class="panda/visual"/>
                <geom mesh="link4_2" material="dark_grey" class="panda/visual"/>
                <geom mesh="link4_3" material="white" class="panda/visual"/>
                <geom mesh="link4_c" class="panda/collision"/>
                <body name="link5" pos="-0.0825 0.384 0" quat="1 -1 0 0">
                  <inertial mass="1.225946" pos="-1.1953e-2 4.1065e-2 -3.8437e-2"
                    fullinertia="3.5549e-2 2.9474e-2 8.627e-3 -2.117e-3 -4.037e-3 2.29e-4"/>
                  <joint name="joint5"/>
                  <site name="joint5"/>
                  <geom mesh="link5_0" material="dark_grey" class="panda/visual"/>
                  <geom mesh="link5_1" material="white" class="panda/visual"/>
                  <geom mesh="link5_2" material="white" class="panda/visual"/>
                  <geom mesh="link5_c0" class="panda/collision"/>
                  <geom mesh="link5_c1" class="panda/collision"/>
                  <geom mesh="link5_c2" class="panda/collision"/>
                  <body name="link6" quat="1 1 0 0">
                    <inertial mass="1.666555" pos="6.0149e-2 -1.4117e-2 -1.0517e-2"
                      fullinertia="1.964e-3 4.354e-3 5.433e-3 1.09e-4 -1.158e-3 3.41e-4"/>
                    <joint name="joint6" range="-0.0175 3.7525"/>
                    <site name="joint6"/>
                    <geom mesh="link6_0" material="off_white" class="panda/visual"/>
                    <geom mesh="link6_1" material="white" class="panda/visual"/>
                    <geom mesh="link6_2" material="dark_grey" class="panda/visual"/>
                    <geom mesh="link6_3" material="white" class="panda/visual"/>
                    <geom mesh="link6_4" material="white" class="panda/visual"/>
                    <geom mesh="link6_5" material="white" class="panda/visual"/>
                    <geom mesh="link6_6" material="white" class="panda/visual"/>
                    <geom mesh="link6_7" material="light_blue" class="panda/visual"/>
                    <geom mesh="link6_8" material="light_blue" class="panda/visual"/>
                    <geom mesh="link6_9" material="dark_grey" class="panda/visual"/>
                    <geom mesh="link6_10" material="dark_grey" class="panda/visual"/>
                    <geom mesh="link6_11" material="white" class="panda/visual"/>
                    <geom mesh="link6_12" material="green" class="panda/visual"/>
                    <geom mesh="link6_13" material="white" class="panda/visual"/>
                    <geom mesh="link6_14" material="dark_grey" class="panda/visual"/>
                    <geom mesh="link6_15" material="dark_grey" class="panda/visual"/>
                    <geom mesh="link6_16" material="white" class="panda/visual"/>
                    <geom mesh="link6_c" class="panda/collision"/>
                    <body name="link7" pos="0.088 0 0" quat="1 1 0 0">
                      <inertial mass="7.35522e-01" pos="1.0517e-2 -4.252e-3 6.1597e-2"
                        fullinertia="1.2516e-2 1.0027e-2 4.815e-3 -4.28e-4 -1.196e-3 -7.41e-4"/>
                      <joint name="joint7"/>
                      <site name="joint7"/>
                      <geom mesh="link7_0" material="white" class="panda/visual"/>
                      <geom mesh="link7_1" material="dark_grey" class="panda/visual"/>
                      <geom mesh="link7_2" material="dark_grey" class="panda/visual"/>
                      <geom mesh="link7_3" material="dark_grey" class="panda/visual"/>
                      <geom mesh="link7_4" material="dark_grey" class="panda/visual"/>
                      <geom mesh="link7_5" material="dark_grey" class="panda/visual"/>
                      <geom mesh="link7_6" material="dark_grey" class="panda/visual"/>
                      <geom mesh="link7_7" material="white" class="panda/visual"/>
                      <geom mesh="link7_c" class="panda/collision"/>
                      <body name="attachment" pos="0 0 0.107" quat="0.3826834 0 0 0.9238795">
                        <camera name="handcam_depth" pos="-0.05 0 0" fovy="62" quat="0 1 -1 0"/>
                        <camera name="handcam_rgb" pos="-0.05 0.015 0" fovy="42.5" quat="0 1 -1 0"/>
                        <site name="attachment_site" quat="0 0 0 1"/>
                        <body name="base_mount" quat="-1 0 0 1">
                        <body name="pinch_body" pos="0.0 0.0 0.33">
                          <geom type="sphere" size="0.01" rgba="1 0 0 1"/>
                          <!-- <site name="sensor12_site_1" type="sphere" size="0.002" pos="0 0 0" rgba="0 0 0 1"/> -->
                          <site name="pinch" pos="0 0 0" size="0.01" rgba="1 0 0 1"/>
                        </body>
                          <geom type="mesh" rgba="0.1 0.1 0.1 1" mesh="fabase"/>
                          <body name="falink2" pos="0 0.028001 0.1905" quat="0.707105 0 0 0.707108">
                            <inertial pos="-0.0047988 -0.000564323 0.026592" quat="0.98377 -0.00522689 -0.157878 0.0851093" mass="0.00600673" diaginertia="1.50497e-06 1.46337e-06 2.28978e-07"/>
                            <joint name="FAJ3" pos="0 0 0" axis="1 0 0" range="-1.5708 1.5708" actuatorfrcrange="-10 10"/>
                            <geom type="mesh" rgba="0.1 0.1 0.1 1" mesh="falink2"/>
                            <geom pos="0 0 0.011" quat="0.707105 0 0 -0.707108" type="mesh" rgba="0.1 0.1 0.1 1" mesh="falink1"/>
                            <body name="pmbase" pos="-0.0193 7.08929e-08 0.05" quat="0.707105 0 0 -0.707108">
                              <inertial pos="0.00386965 -0.0201676 0.043105" quat="0.708131 0.0605489 0.105728 0.69549" mass="0.0350022" diaginertia="2.98712e-05 2.33619e-05 1.0617e-05"/>
                              <joint name="FAJ1" pos="0 0 0" axis="-1 0 0" range="-1.5708 1.5708" actuatorfrcrange="-10 10"/>
                              <geom type="mesh" rgba="0.1 0.1 0.1 1" mesh="pmbase"/>
                              <geom pos="0 -0.0193 0.01" quat="1 0 0 0" type="mesh" rgba="0.1 0.1 0.1 1" mesh="palm"/>
                              <body name="thbase" pos="0.026851 -0.00615 0.048" quat="9.38184e-07 0.707105 -9.38187e-07 0.707108">
                                <inertial pos="-0.00179429 2.09601e-08 0.00147249" quat="0 0.703958 0 0.710242" mass="0.00644353" diaginertia="8.14254e-07 6.9643e-07 5.42691e-07"/>
                                <joint name="THJ4" pos="0 0 0" axis="1 0 0" range="0 1.5708" actuatorfrcrange="-10 10"/>
                                <geom type="mesh" rgba="0.1 0.1 0.1 1" mesh="thbase"/>
                                <body name="thproximal" pos="0 0 0.01575" quat="-3.89602e-06 -0.707107 1.29867e-06 -0.707107">
                                  <inertial pos="0.00638369 -8.78508e-06 -0.000318319" quat="0.442462 0.543069 0.567459 0.432774" mass="0.00874437" diaginertia="8.32014e-07 6.87688e-07 3.5781e-07"/>
                                  <joint name="THJ3" pos="0 0 0" axis="-1 0 0" range="0 1.5708" actuatorfrcrange="-10 10"/>
                                  <geom type="mesh" rgba="0.1 0.1 0.1 1" mesh="thproximal"/>
                                  <body name="thmiddle" pos="0.025 0 0" quat="0.499998 0.5 0.500002 0.5">
                                    <inertial pos="-0.000696295 0.000275415 0.0255327" quat="0.999901 -0.00171624 0.00573467 0.0127579" mass="0.00591298" diaginertia="1.06987e-06 8.91277e-07 2.44924e-07"/>
                                    <joint name="THJ2" pos="0 0 0" axis="-1 0 0" range="0 1.5708" actuatorfrcrange="-10 10"/>
                                    <geom type="mesh" rgba="0.1 0.1 0.1 1" mesh="thmiddle"/>
                                    <body name="thdistal" pos="0 0.003 0.045">
                                      <inertial pos="6.64428e-05 -0.00522039 0.013863" quat="0.702562 0.0350997 -0.0476756 0.709156" mass="0.00260815" diaginertia="3.02781e-07 2.44494e-07 1.00921e-07"/>
                                      <joint name="THJ1" pos="0 0 0" axis="-1 0 0" range="0 1.5708" actuatorfrcrange="-10 10"/>
                                      <geom type="mesh" rgba="0.1 0.1 0.1 1" mesh="thdistal"/>
                                    </body>
                                  </body>
                                </body>
                              </body>
                              <body name="ffbase" pos="0.030504 -0.01885 0.0955" quat="0.707105 0 0 0.707108">
                                <inertial pos="-0.00112189 0.000208476 0.0061788" quat="0.691314 -0.128612 -0.11992 0.70083" mass="0.00757937" diaginertia="5.89985e-07 4.56493e-07 3.21433e-07"/>
                                <joint name="FFJ4" pos="0 0 0" axis="1 0 0" range="-0.1309 0.1309" actuatorfrcrange="-10 10"/>
                                <geom type="mesh" rgba="0.1 0.1 0.1 1" mesh="ffbase"/>
                                <body name="ffproximal" pos="0 0 0.018" quat="0.707105 0 0 -0.707108">
                                  <inertial pos="-0.00196719 -0.000248547 0.0263052" quat="0.999421 0.0171146 0.0100584 0.027621" mass="0.00551109" diaginertia="1.03882e-06 8.70474e-07 2.36547e-07"/>
                                  <joint name="FFJ3" pos="0 0 0" axis="-1 0 0" range="0 1.5708" actuatorfrcrange="-10 10"/>
                                  <geom type="mesh" rgba="0.1 0.1 0.1 1" mesh="ffproximal"/>
                                  <body name="ffmiddle" pos="0 0.003 0.045">
                                    <inertial pos="0.00038263 -0.00305057 0.0123468" quat="0.999902 -0.0115545 -0.00119299 0.00780544" mass="0.00397399" diaginertia="3.35467e-07 2.47426e-07 1.3015e-07"/>
                                    <joint name="FFJ2" pos="0 0 0" axis="-1 0 0" range="0 1.5708" actuatorfrcrange="-10 10"/>
                                    <geom type="mesh" rgba="0.1 0.1 0.1 1" mesh="ffmiddle"/>
                                    <body name="ffdistal" pos="0 0 0.025">
                                      <inertial pos="0.000106131 -0.00174211 0.0146517" quat="0.705302 0.0439439 -0.0324684 0.706798" mass="0.00588198" diaginertia="4.72593e-07 4.26469e-07 1.52131e-07"/>
                                      <joint name="FFJ1" pos="0 0 0" axis="-1 0 0" range="0 1.5708" actuatorfrcrange="-10 10"/>
                                      <geom type="mesh" rgba="0.1 0.1 0.1 1" mesh="ffdistal"/>
                                    </body>
                                  </body>
                                </body>
                              </body>
                              <body name="mfbase" pos="0.0075044 -0.01885 0.1005" quat="0.707105 0 0 0.707108">
                                <inertial pos="-0.00112189 0.000208476 0.0061788" quat="0.691314 -0.128612 -0.11992 0.70083" mass="0.00757937" diaginertia="5.89985e-07 4.56493e-07 3.21433e-07"/>
                                <joint name="MFJ4" pos="0 0 0" axis="1 0 0" range="-0.1309 0.1309" actuatorfrcrange="-10 10"/>
                                <geom type="mesh" rgba="0.1 0.1 0.1 1" mesh="mfbase"/>
                                <body name="mfproximal" pos="0 0 0.018" quat="0.707105 0 0 -0.707108">
                                  <inertial pos="-0.00196719 -0.000248547 0.0263052" quat="0.999421 0.0171146 0.0100584 0.027621" mass="0.00551109" diaginertia="1.03882e-06 8.70474e-07 2.36547e-07"/>
                                  <joint name="MFJ3" pos="0 0 0" axis="-1 0 0" range="0 1.5708" actuatorfrcrange="-10 10"/>
                                  <geom type="mesh" rgba="0.1 0.1 0.1 1" mesh="mfproximal"/>
                                  <body name="mfmiddle" pos="0 0.003 0.045">
                                    <inertial pos="0.00038263 -0.00305057 0.0123468" quat="0.999902 -0.0115545 -0.00119299 0.00780544" mass="0.00397399" diaginertia="3.35467e-07 2.47426e-07 1.3015e-07"/>
                                    <joint name="MFJ2" pos="0 0 0" axis="-1 0 0" range="0 1.5708" actuatorfrcrange="-10 10"/>
                                    <geom type="mesh" rgba="0.1 0.1 0.1 1" mesh="mfmiddle"/>
                                    <body name="mfdistal" pos="0 0 0.025">
                                      <inertial pos="0.000106134 -0.00174211 0.0146517" quat="0.705302 0.0439438 -0.0324684 0.706798" mass="0.00588198" diaginertia="4.72593e-07 4.26469e-07 1.52131e-07"/>
                                      <joint name="MFJ1" pos="0 0 0" axis="-1 0 0" range="0 1.5708" actuatorfrcrange="-10 10"/>
                                      <geom type="mesh" rgba="0.1 0.1 0.1 1" mesh="mfdistal"/>
                                    </body>
                                  </body>
                                </body>
                              </body>
                              <body name="rfbase" pos="-0.015496 -0.01885 0.0955" quat="0.707105 0 0 0.707108">
                                <inertial pos="-0.00112189 0.000208476 0.0061788" quat="0.691314 -0.128612 -0.11992 0.70083" mass="0.00757937" diaginertia="5.89985e-07 4.56493e-07 3.21433e-07"/>
                                <joint name="RFJ4" pos="0 0 0" axis="1 0 0" range="-0.1309 0.1309" actuatorfrcrange="-10 10"/>
                                <geom type="mesh" rgba="0.1 0.1 0.1 1" mesh="rfbase"/>
                                <body name="rfproximal" pos="0 0 0.018" quat="0.707105 0 0 -0.707108">
                                  <inertial pos="-0.00196719 -0.000248547 0.0263052" quat="0.999421 0.0171146 0.0100584 0.027621" mass="0.00551109" diaginertia="1.03882e-06 8.70474e-07 2.36547e-07"/>
                                  <joint name="RFJ3" pos="0 0 0" axis="-1 0 0" range="0 1.5708" actuatorfrcrange="-10 10"/>
                                  <geom type="mesh" rgba="0.1 0.1 0.1 1" mesh="rfproximal"/>
                                  <body name="rfmiddle" pos="0 0.003 0.045">
                                    <inertial pos="0.00038263 -0.00305057 0.0123468" quat="0.999902 -0.0115545 -0.00119299 0.00780544" mass="0.00397399" diaginertia="3.35467e-07 2.47426e-07 1.3015e-07"/>
                                    <joint name="RFJ2" pos="0 0 0" axis="-1 0 0" range="0 1.5708" actuatorfrcrange="-10 10"/>
                                    <geom type="mesh" rgba="0.1 0.1 0.1 1" mesh="rfmiddle"/>
                                    <body name="rfdistal" pos="0 0 0.025">
                                      <inertial pos="0.000105534 -0.00174245 0.0146519" quat="0.705516 0.043956 -0.0324278 0.706586" mass="0.00588145" diaginertia="4.72548e-07 4.2642e-07 1.52074e-07"/>
                                      <joint name="RFJ1" pos="0 0 0" axis="-1 0 0" range="0 1.5708" actuatorfrcrange="-10 10"/>
                                      <geom type="mesh" rgba="0.1 0.1 0.1 1" mesh="rfdistal"/>
                                    </body>
                                  </body>
                                </body>
                              </body>
                              <body name="lfpalm" pos="-0.025779 -0.0193 0.042848" quat="0.866025 0 -0.500001 0">
                                <inertial pos="0.0095207 -0.000716361 0.0177911" quat="0.678248 0.352192 0.363197 0.532944" mass="0.0067837" diaginertia="6.88671e-07 6.64629e-07 3.26717e-07"/>
                                <joint name="LFJ5" pos="0 0 0" axis="-1 0 0" range="0 1.5708" actuatorfrcrange="-10 10"/>
                                <geom type="mesh" rgba="0.1 0.1 0.1 1" mesh="lfpalm"/>
                                <body name="lfbase" pos="0.034911 0.00045 0.034839" quat="0.612371 0.353553 0.353555 0.612373">
                                  <inertial pos="-0.00112189 0.000208476 0.0061788" quat="0.691314 -0.128612 -0.11992 0.70083" mass="0.00757937" diaginertia="5.89985e-07 4.56493e-07 3.21433e-07"/>
                                  <joint name="LFJ4" pos="0 0 0" axis="1 0 0" range="-0.1309 0.1309" actuatorfrcrange="-10 10"/>
                                  <geom type="mesh" rgba="0.1 0.1 0.1 1" mesh="lfbase"/>
                                  <body name="lfproximal" pos="0 0 0.018" quat="0.707105 0 0 -0.707108">
                                    <inertial pos="-0.00196719 -0.000248547 0.0263052" quat="0.999421 0.0171146 0.0100584 0.027621" mass="0.00551109" diaginertia="1.03882e-06 8.70474e-07 2.36547e-07"/>
                                    <joint name="LFJ3" pos="0 0 0" axis="-1 0 0" range="0 1.5708" actuatorfrcrange="-10 10"/>
                                    <geom type="mesh" rgba="0.1 0.1 0.1 1" mesh="lfproximal"/>
                                    <body name="lfmiddle" pos="0 0.003 0.045">
                                      <inertial pos="0.00038263 -0.00305057 0.0123468" quat="0.999902 -0.0115545 -0.00119299 0.00780544" mass="0.00397399" diaginertia="3.35467e-07 2.47426e-07 1.3015e-07"/>
                                      <joint name="LFJ2" pos="0 0 0" axis="-1 0 0" range="0 1.5708" actuatorfrcrange="-10 10"/>
                                      <geom type="mesh" rgba="0.1 0.1 0.1 1" mesh="lfmiddle"/>
                                      <body name="lfdistal" pos="0 0 0.025">
                                        <inertial pos="0.000105517 -0.00174246 0.0146519" quat="0.705516 0.0439556 -0.0324295 0.706586" mass="0.00588144" diaginertia="4.72548e-07 4.26421e-07 1.52074e-07"/>
                                        <joint name="LFJ1" pos="0 0 0" axis="-1 0 0" range="0 1.5708" actuatorfrcrange="-10 10"/>
                                        <geom type="mesh" rgba="0.1 0.1 0.1 1" mesh="lfdistal"/>
                                      </body>
                                    </body>
                                  </body>
                                </body>
                              </body>
                            </body>
                          </body>
                        </body>
                      </body>
                    </body>
                  </body>
                </body>
              </body>
            </body>
          </body>
        </body>
      </body>
    </worldbody>

    <!-- <contact>
      <exclude body1="base" body2="left_driver"/>
      <exclude body1="base" body2="right_driver"/>
      <exclude body1="base" body2="left_spring_link"/>
      <exclude body1="base" body2="right_spring_link"/>
      <exclude body1="right_coupler" body2="right_follower"/>
      <exclude body1="left_coupler" body2="left_follower"/>
    </contact> -->

    <!-- <tendon>
      <fixed name="split">
        <joint joint="right_driver_joint" coef="0.5"/>
        <joint joint="left_driver_joint" coef="0.5"/>
      </fixed>
    </tendon> -->

    <!-- <equality>
      <connect anchor="0 0 0" body1="right_follower" body2="right_coupler" solimp="0.95 0.99 0.001" solref="0.005 1"/>
      <connect anchor="0 0 0" body1="left_follower" body2="left_coupler" solimp="0.95 0.99 0.001" solref="0.005 1"/>
      <joint joint1="right_driver_joint" joint2="left_driver_joint" polycoef="0 1 0 0 0" solimp="0.95 0.99 0.001"
        solref="0.005 1"/>
    </equality> -->

    <actuator>
      <motor class="panda" name="actuator1" joint="joint1" ctrlrange="-87 87"/>
      <motor class="panda" name="actuator2" joint="joint2" ctrlrange="-87 87"/>
      <motor class="panda" name="actuator3" joint="joint3" ctrlrange="-87 87"/>
      <motor class="panda" name="actuator4" joint="joint4" ctrlrange="-87 87"/>
      <motor class="panda" name="actuator5" joint="joint5" ctrlrange="-12 12"/>
      <motor class="panda" name="actuator6" joint="joint6" ctrlrange="-12 12"/>
      <motor class="panda" name="actuator7" joint="joint7" ctrlrange="-12 12"/>
      
      <position name="FAJ3" joint="FAJ3" kp="50" kv="10" gear="1" ctrlrange="-1.57 1.57"/>
      <position name="FAJ1" joint="FAJ1" kp="50" kv="10" gear="1" ctrlrange="-1.57 1.57"/>
      
      <position name="THJ4" joint="THJ4" kp="50" kv="10" gear="1" ctrlrange="0 1.57"/>
      <position name="THJ3" joint="THJ3" kp="50" kv="10" gear="1" ctrlrange="0 1.57"/>
      <position name="THJ2" joint="THJ2" kp="50" kv="10" gear="1" ctrlrange="0 1.57"/>
      <position name="THJ1" joint="THJ1" kp="50" kv="10" gear="1" ctrlrange="0 1.57"/>
      
      <position name="FFJ4" joint="FFJ4" kp="50" kv="10" gear="1" ctrlrange="-0.26 0.26"/>
      <position name="FFJ3" joint="FFJ3" kp="50" kv="10" gear="1" ctrlrange="0 1.57"/>
      <position name="FFJ2" joint="FFJ2" kp="50" kv="10" gear="1" ctrlrange="0 1.57"/>
      <position name="FFJ1" joint="FFJ1" kp="50" kv="10" gear="1" ctrlrange="0 1.57"/>
      
      <position name="MFJ4" joint="MFJ4" kp="50" kv="10" gear="1" ctrlrange="-0.26 0.26"/>
      <position name="MFJ3" joint="MFJ3" kp="50" kv="10" gear="1" ctrlrange="0 1.57"/>
      <position name="MFJ2" joint="MFJ2" kp="50" kv="10" gear="1" ctrlrange="0 1.57"/>
      <position name="MFJ1" joint="MFJ1" kp="50" kv="10" gear="1" ctrlrange="0 1.57"/>
      
      <position name="RFJ4" joint="RFJ4" kp="50" kv="10" gear="1" ctrlrange="-0.26 0.26"/>
      <position name="RFJ3" joint="RFJ3" kp="50" kv="10" gear="1" ctrlrange="0 1.57"/>
      <position name="RFJ2" joint="RFJ2" kp="50" kv="10" gear="1" ctrlrange="0 1.57"/>
      <position name="RFJ1" joint="RFJ1" kp="50" kv="10" gear="1" ctrlrange="0 1.57"/>
      
      <position name="LFJ5" joint="LFJ5" kp="50" kv="10" gear="1" ctrlrange="0 1.57"/>
      <position name="LFJ4" joint="LFJ4" kp="50" kv="10" gear="1" ctrlrange="-0.26 0.26"/>
      <position name="LFJ3" joint="LFJ3" kp="50" kv="10" gear="1" ctrlrange="0 1.57"/>
      <position name="LFJ2" joint="LFJ2" kp="50" kv="10" gear="1" ctrlrange="0 1.57"/>
      <position name="LFJ1" joint="LFJ1" kp="50" kv="10" gear="1" ctrlrange="0 1.57"/>
    </actuator>

    <sensor>
      <jointpos name="panda/joint1_pos" joint="joint1"/>
      <jointpos name="panda/joint2_pos" joint="joint2"/>
      <jointpos name="panda/joint3_pos" joint="joint3"/>
      <jointpos name="panda/joint4_pos" joint="joint4"/>
      <jointpos name="panda/joint5_pos" joint="joint5"/>
      <jointpos name="panda/joint6_pos" joint="joint6"/>
      <jointpos name="panda/joint7_pos" joint="joint7"/>

      <jointvel name="panda/joint1_vel" joint="joint1"/>
      <jointvel name="panda/joint2_vel" joint="joint2"/>
      <jointvel name="panda/joint3_vel" joint="joint3"/>
      <jointvel name="panda/joint4_vel" joint="joint4"/>
      <jointvel name="panda/joint5_vel" joint="joint5"/>
      <jointvel name="panda/joint6_vel" joint="joint6"/>
      <jointvel name="panda/joint7_vel" joint="joint7"/>

      <torque name="panda/joint1_torque" site="joint1"/>
      <torque name="panda/joint2_torque" site="joint2"/>
      <torque name="panda/joint3_torque" site="joint3"/>
      <torque name="panda/joint4_torque" site="joint4"/>
      <torque name="panda/joint5_torque" site="joint5"/>
      <torque name="panda/joint6_torque" site="joint6"/>
      <torque name="panda/joint7_torque" site="joint7"/>

      <force name="panda/wrist_force" site="attachment_site"/>

      <framepos name="botyard/pinch_pos" objtype="site" objname="pinch"/>
      <framequat name="botyard/pinch_quat" objtype="site" objname="pinch"/>
      <framelinvel name="botyard/pinch_vel" objtype="site" objname="pinch"/>
      <frameangvel name="botyard/pinch_angvel" objtype="site" objname="pinch"/>
    </sensor>
  </mujoco>
