<mujoco model="ur16e">
  <option iterations="50" timestep="0.001" solver="PGS" gravity="0 0 -9.81" />

  <compiler angle="radian" eulerseq="zyx" autolimits="true" />

  <default>
    <joint limited="true" damping="0.01" armature="0.01" frictionloss="0.01" />
    <geom condim="4" contype="1" conaffinity="15" friction="0.9 0.2 0.2" solref="0.001 2" />
    <motor ctrllimited="true" />
    <equality solref="0.001 2" />
    <default class="visualgeom">
      <geom material="visualgeom" condim="1" contype="0" conaffinity="0" />
    </default>
  </default>

  <asset>
    <mesh name="base" content_type="model/stl" file="ur16e/meshes/ur10e/collision/base.stl" />
    <mesh name="shoulder" content_type="model/stl" file="ur16e/meshes/ur10e/collision/shoulder.stl" />
    <mesh name="upperarm" content_type="model/stl" file="ur16e/meshes/ur16e/collision/upperarm.stl" />
    <mesh name="forearm" content_type="model/stl" file="ur16e/meshes/ur16e/collision/forearm.stl" />
    <mesh name="wrist1" content_type="model/stl" file="ur16e/meshes/ur10e/collision/wrist1.stl" />
    <mesh name="wrist2" content_type="model/stl" file="ur16e/meshes/ur10e/collision/wrist2.stl" />
    <mesh name="wrist3" content_type="model/stl" file="ur16e/meshes/ur10e/collision/wrist3.stl" />
    <texture name="texplane" type="2d" builtin="checker" rgb1=".0 .0 .0" rgb2=".8 .8 .8" width="100" height="100" />
    <material name="matplane" reflectance="0." texture="texplane" texrepeat="1 1" texuniform="true" />
    <material name="visualgeom" rgba="0.5 0.9 0.2 1" />
  </asset>

  <worldbody>
    <light directional="true" diffuse="0.4 0.4 0.4" specular="0.1 0.1 0.1" pos="0 0 5.0" dir="0 0 -1" castshadow="false" />
    <light directional="true" diffuse="0.6 0.6 0.6" specular="0.2 0.2 0.2" pos="0 0 4" dir="0 0 -1" />
    <geom name="ground" type="plane" pos="0 0 0" size="100 100 0.001" quat="1 0 0 0" material="matplane" condim="3" conaffinity="15" />
    <camera name="fixed" pos="0 -3.0 0.648109286043355" xyaxes="1 0 0 0 0 1" />
    <camera name="track" mode="trackcom" pos="0 -3.0 0.648109286043355" xyaxes="1 0 0 0 0 1" />
    <body name="root" pos="0 0 0.1481092860433551" quat="1 0 0 0">
      <freejoint name="root" />
      <site name="imu" size="0.01" pos="0 0 0" />
      <geom pos="0 0 0" quat="-1 0 0 0" type="mesh" mesh="base" contype="1" conaffinity="0" density="0" group="1" class="visualgeom" />
      <geom type="mesh" rgba="" mesh="base" pos="0 0 0" quat="-1 0 0 0" />
      <body name="shoulder_link" pos="0 0 0.1807" quat="0 0 0 1">
        <inertial pos="0 -0.03 -0.016" quat="0.705507 0.0945828 -0.0925597 0.696238" mass="7.369" diaginertia="0.034757 0.0335098 0.0199832" />
        <joint name="shoulder_pan_joint" pos="0 0 0" axis="0 0 1" range="-6.28319 6.28319" actuatorfrcrange="-330 330" />
        <geom quat="0 0 0 1" type="mesh" mesh="shoulder" contype="1" conaffinity="0" density="0" group="1" class="visualgeom" />
        <geom type="mesh" rgba="" mesh="shoulder" quat="0 0 0 1" />
        <body name="upper_arm_link" quat="0.707107 0.707107 0 0">
          <inertial pos="-0.1764 0 0.16" quat="0.0126173 0.701296 0.0125722 0.712647" mass="10.45" diaginertia="0.476467 0.475579 0.0278444" />
          <joint name="shoulder_lift_joint" pos="0 0 0" axis="0 0 1" range="-6.28319 6.28319" actuatorfrcrange="-330 330" />
          <geom pos="0 0 0.176" quat="0.5 0.5 -0.5 -0.5" type="mesh" mesh="upperarm" contype="1" conaffinity="0" density="0" group="1" class="visualgeom" />
          <geom type="mesh" rgba="" mesh="upperarm" pos="0 0 0.176" quat="0.5 0.5 -0.5 -0.5" />
          <body name="forearm_link" pos="-0.4784 0 0">
            <inertial pos="-0.166 0 0.065" quat="0.474576 0.524723 0.521214 0.477262" mass="4.321" diaginertia="0.1206 0.118095 0.00995448" />
            <joint name="elbow_joint" pos="0 0 0" axis="0 0 1" range="-3.14159 3.14159" actuatorfrcrange="-150 150" />
            <geom pos="0 0 0.04" quat="0.5 0.5 -0.5 -0.5" type="mesh" mesh="forearm" contype="1" conaffinity="0" density="0" group="1" class="visualgeom" />
            <geom type="mesh" rgba="" mesh="forearm" pos="0 0 0.04" quat="0.5 0.5 -0.5 -0.5" />
            <body name="wrist_1_link" pos="-0.36 0 0.17415">
              <inertial pos="0 -0.011 -0.009" quat="0.783712 0.621027 0.00575209 -0.00930279" mass="2.18" diaginertia="0.00609007 0.00598484 0.00225509" />
              <joint name="wrist_1_joint" pos="0 0 0" axis="0 0 1" range="-6.28319 6.28319" actuatorfrcrange="-54 54" />
              <geom pos="0 0 -0.135" quat="0.707107 0.707107 0 0" type="mesh" mesh="wrist1" contype="1" conaffinity="0" density="0" group="1" class="visualgeom" />
              <geom type="mesh" rgba="" mesh="wrist1" pos="0 0 -0.135" quat="0.707107 0.707107 0 0" />
              <body name="wrist_2_link" pos="0 -0.11985 -2.45816e-11" quat="0.707107 0.707107 0 0">
                <inertial pos="0 0.012 -0.018" quat="0.601786 0.798584 -0.00998004 0.00423019" mass="2.033" diaginertia="0.00389011 0.003759 0.00206089" />
                <joint name="wrist_2_joint" pos="0 0 0" axis="0 0 1" range="-6.28319 6.28319" actuatorfrcrange="-54 54" />
                <geom pos="0 0 -0.12" quat="1 0 0 0" type="mesh" mesh="wrist2" contype="1" conaffinity="0" density="0" group="1" class="visualgeom" />
                <geom type="mesh" rgba="" mesh="wrist2" pos="0 0 -0.12" quat="1 0 0 0" />
                <body name="wrist_3_link" pos="0 0.11655 -2.39048e-11" quat="0.707107 -0.707107 0 0">
                  <inertial pos="0 0 -0.044" quat="0.707107 0 0 0.707107" mass="0.907" diaginertia="0.00118 0.00117 0.00084" />
                  <joint name="wrist_3_joint" pos="0 0 0" axis="0 0 1" range="-6.28319 6.28319" actuatorfrcrange="-54 54" />
                  <geom pos="0 0 -0.1168" quat="0.707107 0.707107 0 0" type="mesh" mesh="wrist3" contype="1" conaffinity="0" density="0" group="1" class="visualgeom" />
                  <geom type="mesh" rgba="" mesh="wrist3" pos="0 0 -0.1168" quat="0.707107 0.707107 0 0" />
                </body>
              </body>
            </body>
          </body>
        </body>
      </body>
    </body>
  </worldbody>

  <actuator>
    <motor name="shoulder_pan_joint" joint="shoulder_pan_joint" ctrllimited="true" ctrlrange="-330 330" gear="1" />
    <motor name="shoulder_lift_joint" joint="shoulder_lift_joint" ctrllimited="true" ctrlrange="-330 330" gear="1" />
    <motor name="elbow_joint" joint="elbow_joint" ctrllimited="true" ctrlrange="-150 150" gear="1" />
    <motor name="wrist_1_joint" joint="wrist_1_joint" ctrllimited="true" ctrlrange="-54 54" gear="1" />
    <motor name="wrist_2_joint" joint="wrist_2_joint" ctrllimited="true" ctrlrange="-54 54" gear="1" />
    <motor name="wrist_3_joint" joint="wrist_3_joint" ctrllimited="true" ctrlrange="-54 54" gear="1" />
  </actuator>

  <sensor>
    <actuatorpos name="shoulder_pan_joint_p" actuator="shoulder_pan_joint" />
    <actuatorvel name="shoulder_pan_joint_v" actuator="shoulder_pan_joint" />
    <actuatorfrc name="shoulder_pan_joint_f" actuator="shoulder_pan_joint" noise="0.001" />
    <actuatorpos name="shoulder_lift_joint_p" actuator="shoulder_lift_joint" />
    <actuatorvel name="shoulder_lift_joint_v" actuator="shoulder_lift_joint" />
    <actuatorfrc name="shoulder_lift_joint_f" actuator="shoulder_lift_joint" noise="0.001" />
    <actuatorpos name="elbow_joint_p" actuator="elbow_joint" />
    <actuatorvel name="elbow_joint_v" actuator="elbow_joint" />
    <actuatorfrc name="elbow_joint_f" actuator="elbow_joint" noise="0.001" />
    <actuatorpos name="wrist_1_joint_p" actuator="wrist_1_joint" />
    <actuatorvel name="wrist_1_joint_v" actuator="wrist_1_joint" />
    <actuatorfrc name="wrist_1_joint_f" actuator="wrist_1_joint" noise="0.001" />
    <actuatorpos name="wrist_2_joint_p" actuator="wrist_2_joint" />
    <actuatorvel name="wrist_2_joint_v" actuator="wrist_2_joint" />
    <actuatorfrc name="wrist_2_joint_f" actuator="wrist_2_joint" noise="0.001" />
    <actuatorpos name="wrist_3_joint_p" actuator="wrist_3_joint" />
    <actuatorvel name="wrist_3_joint_v" actuator="wrist_3_joint" />
    <actuatorfrc name="wrist_3_joint_f" actuator="wrist_3_joint" noise="0.001" />
    <framequat name="orientation" objtype="site" noise="0.001" objname="imu" />
    <gyro name="angular-velocity" site="imu" noise="0.005" cutoff="34.9" />
  </sensor>
</mujoco>