<?xml version="1.0" ?>
<!-- =================================================================================== -->
<!-- |    This document was autogenerated by xacro from /home/orin/Documents/dexhand_ur_demo_ws/install/ur_dexhand_description/share/ur_dexhand_description/urdf/ur_dexhand.urdf.xacro | -->
<!-- |    EDITING THIS FILE BY HAND IS NOT RECOMMENDED                                 | -->
<!-- =================================================================================== -->
<robot name="ur_dexhand">
  <!-- The world link -->
  <link name="world"/>
  <!--
    Base UR robot series xacro macro.

    NOTE this is NOT a URDF. It cannot directly be loaded by consumers
    expecting a flattened '.urdf' file. See the top-level '.xacro' for that
    (but note that .xacro must still be processed by the xacro command).

    This file models the base kinematic chain of a UR robot, which then gets
    parameterised by various configuration files to convert it into a UR3(e),
    UR5(e), UR10(e) or UR16e.

    NOTE the default kinematic parameters (i.e., link lengths, frame locations,
    offsets, etc) do not correspond to any particular robot. They are defaults
    only. There WILL be non-zero offsets between the Forward Kinematics results
    in TF (i.e., robot_state_publisher) and the values reported by the Teach
    Pendant.

    For accurate (and robot-specific) transforms, the 'kinematics_parameters_file'
    parameter MUST point to a .yaml file containing the appropriate values for
    the targeted robot.

    If using the UniversalRobots/Universal_Robots_ROS_Driver, follow the steps
    described in the readme of that repository to extract the kinematic
    calibration from the controller and generate the required .yaml file.

    Main author of the migration to yaml configs Ludovic Delval.

    Contributors to previous versions (in no particular order)

     - Denis Stogl
     - Lovro Ivanov
     - Felix Messmer
     - Kelsey Hawkins
     - Wim Meeussen
     - Shaun Edwards
     - Nadia Hammoudeh Garcia
     - Dave Hershberger
     - G. vd. Hoorn
     - Philip Long
     - Dave Coleman
     - Miguel Prada
     - Mathias Luedtke
     - Marcel Schnirring
     - Felix von Drigalski
     - Felix Exner
     - Jimmy Da Silva
     - Ajit Krisshna N L
     - Muhammad Asif Rana
  -->
  <!--
    NOTE the macro defined in this file is NOT part of the public API of this
          package. Users CANNOT rely on this file being available, or stored in
          this location. Nor can they rely on the existence of the macro.
  -->
  <ros2_control name="ur_manipulator" type="system">
    <hardware>
      <plugin>mock_components/GenericSystem</plugin>
      <param name="fake_sensor_commands">False</param>
      <param name="state_following_offset">0.0</param>
      <param name="calculate_dynamics">true</param>
    </hardware>
    <joint name="shoulder_pan_joint">
      <command_interface name="position"/>
      <command_interface name="velocity"/>
      <state_interface name="position">
        <!-- initial position for the FakeSystem and simulation -->
        <param name="initial_value">0.0</param>
      </state_interface>
      <state_interface name="velocity"/>
      <state_interface name="effort"/>
    </joint>
    <joint name="shoulder_lift_joint">
      <command_interface name="position"/>
      <command_interface name="velocity"/>
      <state_interface name="position">
        <!-- initial position for the FakeSystem and simulation -->
        <param name="initial_value">-1.57</param>
      </state_interface>
      <state_interface name="velocity"/>
      <state_interface name="effort"/>
    </joint>
    <joint name="elbow_joint">
      <command_interface name="position"/>
      <command_interface name="velocity"/>
      <state_interface name="position">
        <!-- initial position for the FakeSystem and simulation -->
        <param name="initial_value">0.0</param>
      </state_interface>
      <state_interface name="velocity"/>
      <state_interface name="effort"/>
    </joint>
    <joint name="wrist_1_joint">
      <command_interface name="position"/>
      <command_interface name="velocity"/>
      <state_interface name="position">
        <!-- initial position for the FakeSystem and simulation -->
        <param name="initial_value">-1.57</param>
      </state_interface>
      <state_interface name="velocity"/>
      <state_interface name="effort"/>
    </joint>
    <joint name="wrist_2_joint">
      <command_interface name="position"/>
      <command_interface name="velocity"/>
      <state_interface name="position">
        <!-- initial position for the FakeSystem and simulation -->
        <param name="initial_value">0.0</param>
      </state_interface>
      <state_interface name="velocity"/>
      <state_interface name="effort"/>
    </joint>
    <joint name="wrist_3_joint">
      <command_interface name="position"/>
      <command_interface name="velocity"/>
      <state_interface name="position">
        <!-- initial position for the FakeSystem and simulation -->
        <param name="initial_value">0.0</param>
      </state_interface>
      <state_interface name="velocity"/>
      <state_interface name="effort"/>
    </joint>
    <sensor name="tcp_fts_sensor">
      <state_interface name="force.x"/>
      <state_interface name="force.y"/>
      <state_interface name="force.z"/>
      <state_interface name="torque.x"/>
      <state_interface name="torque.y"/>
      <state_interface name="torque.z"/>
    </sensor>
    <sensor name="tcp_pose">
      <state_interface name="position.x"/>
      <state_interface name="position.y"/>
      <state_interface name="position.z"/>
      <state_interface name="orientation.x"/>
      <state_interface name="orientation.y"/>
      <state_interface name="orientation.z"/>
      <state_interface name="orientation.w"/>
    </sensor>
    <!-- NOTE The following are joints used only for testing with fake hardware and will change in the future -->
    <gpio name="speed_scaling">
      <state_interface name="speed_scaling_factor"/>
      <param name="initial_speed_scaling_factor">1</param>
      <command_interface name="target_speed_fraction_cmd"/>
      <command_interface name="target_speed_fraction_async_success"/>
    </gpio>
    <gpio name="gpio">
      <command_interface name="standard_digital_output_cmd_0"/>
      <command_interface name="standard_digital_output_cmd_1"/>
      <command_interface name="standard_digital_output_cmd_2"/>
      <command_interface name="standard_digital_output_cmd_3"/>
      <command_interface name="standard_digital_output_cmd_4"/>
      <command_interface name="standard_digital_output_cmd_5"/>
      <command_interface name="standard_digital_output_cmd_6"/>
      <command_interface name="standard_digital_output_cmd_7"/>
      <command_interface name="standard_digital_output_cmd_8"/>
      <command_interface name="standard_digital_output_cmd_9"/>
      <command_interface name="standard_digital_output_cmd_10"/>
      <command_interface name="standard_digital_output_cmd_11"/>
      <command_interface name="standard_digital_output_cmd_12"/>
      <command_interface name="standard_digital_output_cmd_13"/>
      <command_interface name="standard_digital_output_cmd_14"/>
      <command_interface name="standard_digital_output_cmd_15"/>
      <command_interface name="standard_digital_output_cmd_16"/>
      <command_interface name="standard_digital_output_cmd_17"/>
      <command_interface name="standard_analog_output_cmd_0"/>
      <command_interface name="standard_analog_output_cmd_1"/>
      <command_interface name="analog_output_domain_cmd"/>
      <command_interface name="tool_voltage_cmd"/>
      <command_interface name="io_async_success"/>
      <state_interface name="digital_output_0"/>
      <state_interface name="digital_output_1"/>
      <state_interface name="digital_output_2"/>
      <state_interface name="digital_output_3"/>
      <state_interface name="digital_output_4"/>
      <state_interface name="digital_output_5"/>
      <state_interface name="digital_output_6"/>
      <state_interface name="digital_output_7"/>
      <state_interface name="digital_output_8"/>
      <state_interface name="digital_output_9"/>
      <state_interface name="digital_output_10"/>
      <state_interface name="digital_output_11"/>
      <state_interface name="digital_output_12"/>
      <state_interface name="digital_output_13"/>
      <state_interface name="digital_output_14"/>
      <state_interface name="digital_output_15"/>
      <state_interface name="digital_output_16"/>
      <state_interface name="digital_output_17"/>
      <state_interface name="digital_input_0"/>
      <state_interface name="digital_input_1"/>
      <state_interface name="digital_input_2"/>
      <state_interface name="digital_input_3"/>
      <state_interface name="digital_input_4"/>
      <state_interface name="digital_input_5"/>
      <state_interface name="digital_input_6"/>
      <state_interface name="digital_input_7"/>
      <state_interface name="digital_input_8"/>
      <state_interface name="digital_input_9"/>
      <state_interface name="digital_input_10"/>
      <state_interface name="digital_input_11"/>
      <state_interface name="digital_input_12"/>
      <state_interface name="digital_input_13"/>
      <state_interface name="digital_input_14"/>
      <state_interface name="digital_input_15"/>
      <state_interface name="digital_input_16"/>
      <state_interface name="digital_input_17"/>
      <state_interface name="standard_analog_output_0"/>
      <state_interface name="standard_analog_output_1"/>
      <state_interface name="standard_analog_input_0"/>
      <state_interface name="standard_analog_input_1"/>
      <state_interface name="analog_io_type_0"/>
      <state_interface name="analog_io_type_1"/>
      <state_interface name="analog_io_type_2"/>
      <state_interface name="analog_io_type_3"/>
      <state_interface name="tool_mode"/>
      <state_interface name="tool_output_voltage"/>
      <state_interface name="tool_output_current"/>
      <state_interface name="tool_temperature"/>
      <state_interface name="tool_analog_input_0"/>
      <state_interface name="tool_analog_input_1"/>
      <state_interface name="tool_analog_input_type_0"/>
      <state_interface name="tool_analog_input_type_1"/>
      <state_interface name="robot_mode"/>
      <state_interface name="robot_status_bit_0"/>
      <state_interface name="robot_status_bit_1"/>
      <state_interface name="robot_status_bit_2"/>
      <state_interface name="robot_status_bit_3"/>
      <state_interface name="safety_mode"/>
      <state_interface name="safety_status_bit_0"/>
      <state_interface name="safety_status_bit_1"/>
      <state_interface name="safety_status_bit_2"/>
      <state_interface name="safety_status_bit_3"/>
      <state_interface name="safety_status_bit_4"/>
      <state_interface name="safety_status_bit_5"/>
      <state_interface name="safety_status_bit_6"/>
      <state_interface name="safety_status_bit_7"/>
      <state_interface name="safety_status_bit_8"/>
      <state_interface name="safety_status_bit_9"/>
      <state_interface name="safety_status_bit_10"/>
      <state_interface name="program_running"/>
    </gpio>
    <gpio name="payload">
      <command_interface name="mass"/>
      <command_interface name="cog.x"/>
      <command_interface name="cog.y"/>
      <command_interface name="cog.z"/>
      <command_interface name="payload_async_success"/>
    </gpio>
    <gpio name="resend_robot_program">
      <command_interface name="resend_robot_program_cmd"/>
      <command_interface name="resend_robot_program_async_success"/>
    </gpio>
    <gpio name="hand_back_control">
      <command_interface name="hand_back_control_cmd"/>
      <command_interface name="hand_back_control_async_success"/>
    </gpio>
    <gpio name="zero_ftsensor">
      <command_interface name="zero_ftsensor_cmd"/>
      <command_interface name="zero_ftsensor_async_success"/>
    </gpio>
    <gpio name="freedrive_mode">
      <command_interface name="async_success"/>
      <command_interface name="enable"/>
      <command_interface name="abort"/>
    </gpio>
    <gpio name="tool_contact">
      <command_interface name="tool_contact_set_state"/>
      <state_interface name="tool_contact_result"/>
      <state_interface name="tool_contact_state"/>
    </gpio>
    <gpio name="system_interface">
      <state_interface name="initialized"/>
    </gpio>
    <gpio name="force_mode">
      <command_interface name="task_frame_x"/>
      <command_interface name="task_frame_y"/>
      <command_interface name="task_frame_z"/>
      <command_interface name="task_frame_rx"/>
      <command_interface name="task_frame_ry"/>
      <command_interface name="task_frame_rz"/>
      <command_interface name="selection_vector_x"/>
      <command_interface name="selection_vector_y"/>
      <command_interface name="selection_vector_z"/>
      <command_interface name="selection_vector_rx"/>
      <command_interface name="selection_vector_ry"/>
      <command_interface name="selection_vector_rz"/>
      <command_interface name="wrench_x"/>
      <command_interface name="wrench_y"/>
      <command_interface name="wrench_z"/>
      <command_interface name="wrench_rx"/>
      <command_interface name="wrench_ry"/>
      <command_interface name="wrench_rz"/>
      <command_interface name="limits_x"/>
      <command_interface name="limits_y"/>
      <command_interface name="limits_z"/>
      <command_interface name="limits_rx"/>
      <command_interface name="limits_ry"/>
      <command_interface name="limits_rz"/>
      <command_interface name="type"/>
      <command_interface name="damping"/>
      <command_interface name="gain_scaling"/>
      <command_interface name="disable_cmd"/>
      <command_interface name="force_mode_async_success"/>
    </gpio>
    <gpio name="trajectory_passthrough">
      <command_interface name="setpoint_positions_0"/>
      <command_interface name="setpoint_positions_1"/>
      <command_interface name="setpoint_positions_2"/>
      <command_interface name="setpoint_positions_3"/>
      <command_interface name="setpoint_positions_4"/>
      <command_interface name="setpoint_positions_5"/>
      <command_interface name="setpoint_velocities_0"/>
      <command_interface name="setpoint_velocities_1"/>
      <command_interface name="setpoint_velocities_2"/>
      <command_interface name="setpoint_velocities_3"/>
      <command_interface name="setpoint_velocities_4"/>
      <command_interface name="setpoint_velocities_5"/>
      <command_interface name="setpoint_accelerations_0"/>
      <command_interface name="setpoint_accelerations_1"/>
      <command_interface name="setpoint_accelerations_2"/>
      <command_interface name="setpoint_accelerations_3"/>
      <command_interface name="setpoint_accelerations_4"/>
      <command_interface name="setpoint_accelerations_5"/>
      <command_interface name="transfer_state"/>
      <command_interface name="time_from_start"/>
      <command_interface name="abort"/>
    </gpio>
    <gpio name="get_robot_software_version">
      <state_interface name="get_version_major"/>
      <state_interface name="get_version_minor"/>
      <state_interface name="get_version_build"/>
      <state_interface name="get_version_bugfix"/>
    </gpio>
  </ros2_control>
  <!-- Add URDF transmission elements (for ros_control) -->
  <!--<xacro:ur_arm_transmission prefix="${prefix}" hw_interface="${transmission_hw_interface}" />-->
  <!-- Placeholder for ros2_control transmission which don't yet exist -->
  <!-- links -  main serial chain -->
  <link name="base_link"/>
  <link name="base_link_inertia">
    <visual>
      <origin rpy="0 0 3.141592653589793" xyz="0 0 0"/>
      <geometry>
        <mesh filename="ur16e/meshes/ur10e/visual/base.dae"/>
      </geometry>
    </visual>
    <collision>
      <origin rpy="0 0 3.141592653589793" xyz="0 0 0"/>
      <geometry>
        <mesh filename="ur16e/meshes/ur10e/collision/base.stl"/>
      </geometry>
    </collision>
    <inertial>
      <mass value="4.0"/>
      <origin rpy="0 0 0" xyz="0 0 0"/>
      <inertia ixx="0.0061063308908" ixy="0.0" ixz="0.0" iyy="0.0061063308908" iyz="0.0" izz="0.01125"/>
    </inertial>
  </link>
  <link name="shoulder_link">
    <visual>
      <origin rpy="0 0 3.141592653589793" xyz="0 0 0"/>
      <geometry>
        <mesh filename="ur16e/meshes/ur10e/visual/shoulder.dae"/>
      </geometry>
    </visual>
    <collision>
      <origin rpy="0 0 3.141592653589793" xyz="0 0 0"/>
      <geometry>
        <mesh filename="ur16e/meshes/ur10e/collision/shoulder.stl"/>
      </geometry>
    </collision>
    <inertial>
      <mass value="7.369"/>
      <origin rpy="1.570796326794897 0 0" xyz="0.0 -0.03 -0.016"/>
      <inertia ixx="0.03351" ixy="2e-05" ixz="-1e-05" iyy="0.03374" iyz="0.00374" izz="0.021"/>
    </inertial>
  </link>
  <link name="upper_arm_link">
    <visual>
      <origin rpy="1.5707963267948966 0 -1.5707963267948966" xyz="0 0 0.176"/>
      <geometry>
        <mesh filename="ur16e/meshes/ur16e/visual/upperarm.dae"/>
      </geometry>
    </visual>
    <collision>
      <origin rpy="1.5707963267948966 0 -1.5707963267948966" xyz="0 0 0.176"/>
      <geometry>
        <mesh filename="ur16e/meshes/ur16e/collision/upperarm.stl"/>
      </geometry>
    </collision>
    <inertial>
      <mass value="10.45"/>
      <origin rpy="0 0 0" xyz="-0.1764 0.0 0.16"/>
      <inertia ixx="0.02796" ixy="-0.0001" ixz="-0.0072" iyy="0.47558" iyz="3e-05" izz="0.47635"/>
    </inertial>
  </link>
  <link name="forearm_link">
    <visual>
      <origin rpy="1.5707963267948966 0 -1.5707963267948966" xyz="0 0 0.04"/>
      <geometry>
        <mesh filename="ur16e/meshes/ur16e/visual/forearm.dae"/>
      </geometry>
    </visual>
    <collision>
      <origin rpy="1.5707963267948966 0 -1.5707963267948966" xyz="0 0 0.04"/>
      <geometry>
        <mesh filename="ur16e/meshes/ur16e/collision/forearm.stl"/>
      </geometry>
    </collision>
    <inertial>
      <mass value="4.321"/>
      <origin rpy="0 0 0" xyz="-0.166 0.0 0.065"/>
      <inertia ixx="0.01091" ixy="6e-05" ixz="0.01012" iyy="0.1206" iyz="1e-05" izz="0.11714"/>
    </inertial>
  </link>
  <link name="wrist_1_link">
    <visual>
      <origin rpy="1.5707963267948966 0 0" xyz="0 0 -0.135"/>
      <geometry>
        <mesh filename="ur16e/meshes/ur10e/visual/wrist1.dae"/>
      </geometry>
    </visual>
    <collision>
      <origin rpy="1.5707963267948966 0 0" xyz="0 0 -0.135"/>
      <geometry>
        <mesh filename="ur16e/meshes/ur10e/collision/wrist1.stl"/>
      </geometry>
    </collision>
    <inertial>
      <mass value="2.18"/>
      <origin rpy="1.570796326794897 0 0" xyz="0.0 -0.011 -0.009"/>
      <inertia ixx="0.00609" ixy="-1e-05" ixz="0.0" iyy="0.00245" iyz="0.00083" izz="0.00579"/>
    </inertial>
  </link>
  <link name="wrist_2_link">
    <visual>
      <origin rpy="0 0 0" xyz="0 0 -0.12"/>
      <geometry>
        <mesh filename="ur16e/meshes/ur10e/visual/wrist2.dae"/>
      </geometry>
    </visual>
    <collision>
      <origin rpy="0 0 0" xyz="0 0 -0.12"/>
      <geometry>
        <mesh filename="ur16e/meshes/ur10e/collision/wrist2.stl"/>
      </geometry>
    </collision>
    <inertial>
      <mass value="2.033"/>
      <origin rpy="-1.570796326794897 0 0" xyz="0.0 0.012 -0.018"/>
      <inertia ixx="0.00389" ixy="-1e-05" ixz="0.0" iyy="0.00219" iyz="-0.00045" izz="0.00363"/>
    </inertial>
  </link>
  <link name="wrist_3_link">
    <visual>
      <origin rpy="1.5707963267948966 0 0" xyz="0 0 -0.1168"/>
      <geometry>
        <mesh filename="ur16e/meshes/ur10e/visual/wrist3.dae"/>
      </geometry>
    </visual>
    <collision>
      <origin rpy="1.5707963267948966 0 0" xyz="0 0 -0.1168"/>
      <geometry>
        <mesh filename="ur16e/meshes/ur10e/collision/wrist3.stl"/>
      </geometry>
    </collision>
    <inertial>
      <mass value="0.907"/>
      <origin rpy="0 0 0" xyz="0.0 0.0 -0.044"/>
      <inertia ixx="0.00117" ixy="0.0" ixz="0.0" iyy="0.00118" iyz="0.0" izz="0.00084"/>
    </inertial>
  </link>
  <!-- base_joint fixes base_link to the environment -->
  <joint name="base_joint" type="fixed">
    <origin rpy="0 0 0" xyz="0 0 0.6"/>
    <parent link="world"/>
    <child link="base_link"/>
  </joint>
  <!-- joints - main serial chain -->
  <joint name="base_link-base_link_inertia" type="fixed">
    <parent link="base_link"/>
    <child link="base_link_inertia"/>
    <!-- 'base_link' is REP-103 aligned (so X+ forward), while the internal
           frames of the robot/controller have X+ pointing backwards.
           Use the joint between 'base_link' and 'base_link_inertia' (a dummy
           link/frame) to introduce the necessary rotation over Z (of pi rad).
      -->
    <origin rpy="0 0 3.141592653589793" xyz="0 0 0"/>
  </joint>
  <joint name="shoulder_pan_joint" type="revolute">
    <parent link="base_link_inertia"/>
    <child link="shoulder_link"/>
    <origin rpy="0 0 0" xyz="0 0 0.1807"/>
    <axis xyz="0 0 1"/>
    <limit effort="330.0" lower="-6.283185307179586" upper="6.283185307179586" velocity="2.0943951023931953"/>
    <safety_controller k_position="20" k_velocity="0.0" soft_lower_limit="-6.133185307179586" soft_upper_limit="6.133185307179586"/>
    <dynamics damping="0" friction="0"/>
  </joint>
  <joint name="shoulder_lift_joint" type="revolute">
    <parent link="shoulder_link"/>
    <child link="upper_arm_link"/>
    <origin rpy="1.570796327 0 0" xyz="0 0 0"/>
    <axis xyz="0 0 1"/>
    <limit effort="330.0" lower="-6.283185307179586" upper="6.283185307179586" velocity="2.0943951023931953"/>
    <safety_controller k_position="20" k_velocity="0.0" soft_lower_limit="-6.133185307179586" soft_upper_limit="6.133185307179586"/>
    <dynamics damping="0" friction="0"/>
  </joint>
  <joint name="elbow_joint" type="revolute">
    <parent link="upper_arm_link"/>
    <child link="forearm_link"/>
    <origin rpy="0 0 0" xyz="-0.4784 0 0"/>
    <axis xyz="0 0 1"/>
    <limit effort="150.0" lower="-3.141592653589793" upper="3.141592653589793" velocity="3.141592653589793"/>
    <safety_controller k_position="20" k_velocity="0.0" soft_lower_limit="-2.991592653589793" soft_upper_limit="2.991592653589793"/>
    <dynamics damping="0" friction="0"/>
  </joint>
  <joint name="wrist_1_joint" type="revolute">
    <parent link="forearm_link"/>
    <child link="wrist_1_link"/>
    <origin rpy="0 0 0" xyz="-0.36 0 0.17415"/>
    <axis xyz="0 0 1"/>
    <limit effort="54.0" lower="-6.283185307179586" upper="6.283185307179586" velocity="3.141592653589793"/>
    <safety_controller k_position="20" k_velocity="0.0" soft_lower_limit="-6.133185307179586" soft_upper_limit="6.133185307179586"/>
    <dynamics damping="0" friction="0"/>
  </joint>
  <joint name="wrist_2_joint" type="revolute">
    <parent link="wrist_1_link"/>
    <child link="wrist_2_link"/>
    <origin rpy="1.570796327 0 0" xyz="0 -0.11985 -2.458164590756244e-11"/>
    <axis xyz="0 0 1"/>
    <limit effort="54.0" lower="-6.283185307179586" upper="6.283185307179586" velocity="3.141592653589793"/>
    <safety_controller k_position="20" k_velocity="0.0" soft_lower_limit="-6.133185307179586" soft_upper_limit="6.133185307179586"/>
    <dynamics damping="0" friction="0"/>
  </joint>
  <joint name="wrist_3_joint" type="revolute">
    <parent link="wrist_2_link"/>
    <child link="wrist_3_link"/>
    <origin rpy="1.570796326589793 3.141592653589793 3.141592653589793" xyz="0 0.11655 -2.390480459346185e-11"/>
    <axis xyz="0 0 1"/>
    <limit effort="54.0" lower="-6.283185307179586" upper="6.283185307179586" velocity="3.141592653589793"/>
    <safety_controller k_position="20" k_velocity="0.0" soft_lower_limit="-6.133185307179586" soft_upper_limit="6.133185307179586"/>
    <dynamics damping="0" friction="0"/>
  </joint>
  <link name="ft_frame"/>
  <joint name="wrist_3_link-ft_frame" type="fixed">
    <parent link="wrist_3_link"/>
    <child link="ft_frame"/>
    <origin rpy="3.141592653589793 0 0" xyz="0 0 0"/>
  </joint>
  <!-- ROS-Industrial 'base' frame - base_link to UR 'Base' Coordinates transform -->
  <link name="base"/>
  <joint name="base_link-base_fixed_joint" type="fixed">
    <!-- Note the rotation over Z of pi radians - as base_link is REP-103
           aligned (i.e., has X+ forward, Y+ left and Z+ up), this is needed
           to correctly align 'base' with the 'Base' coordinate system of
           the UR controller.
      -->
    <origin rpy="0 0 3.141592653589793" xyz="0 0 0"/>
    <parent link="base_link"/>
    <child link="base"/>
  </joint>
  <!-- ROS-Industrial 'flange' frame - attachment point for EEF models -->
  <link name="flange"/>
  <joint name="wrist_3-flange" type="fixed">
    <parent link="wrist_3_link"/>
    <child link="flange"/>
    <origin rpy="0 -1.5707963267948966 -1.5707963267948966" xyz="0 0 0"/>
  </joint>
  <!-- ROS-Industrial 'tool0' frame - all-zeros tool frame -->
  <link name="tool0"/>
  <joint name="flange-tool0" type="fixed">
    <!-- default toolframe - X+ left, Y+ up, Z+ front -->
    <origin rpy="1.5707963267948966 0 1.5707963267948966" xyz="0 0 0"/>
    <parent link="flange"/>
    <child link="tool0"/>
  </joint>
  <!-- define a joint connect to other part of robot -->
  <!-- 使用 prefix 参数为关节命名 -->
  <joint name="FOREARM" type="fixed">
    <origin rpy="0 0 3.141592653589793" xyz="0 0 0"/>
    <parent link="tool0"/>
    <!-- 使用 prefix 参数为连杆命名 -->
    <child link="fabase"/>
  </joint>
  <!-- pure URDF goes below -->
  <!-- 使用 prefix 参数为连杆命名 -->
  <link name="fabase">
    <inertial>
      <origin rpy="0 0 0" xyz="3.28758629066675E-07 -0.00280049370465237 0.0716119954420033"/>
      <mass value="0.116733232194003"/>
      <inertia ixx="0.000208688922136791" ixy="-1.09031140514313E-09" ixz="-2.33671160073293E-11" iyy="0.00019711724481563" iyz="-1.2662112896217E-06" izz="0.000114813277747077"/>
    </inertial>
    <visual>
      <origin rpy="0 0 0" xyz="0 0 0"/>
      <geometry>
        <mesh filename="botyard_hand/meshes/fabase.STL"/>
      </geometry>
      <material name="">
        <color rgba="1 1 1 1"/>
      </material>
    </visual>
    <collision>
      <origin rpy="0 0 0" xyz="0 0 0"/>
      <geometry>
        <mesh filename="botyard_hand/meshes/fabase.STL"/>
      </geometry>
    </collision>
  </link>
  <!-- 使用 prefix 参数为连杆命名 -->
  <link name="falink2">
    <inertial>
      <origin rpy="0 0 0" xyz="8.10398166975479E-09 -4.01177173158664E-10 0.00549999656729894"/>
      <mass value="0.00127776584823899"/>
      <inertia ixx="5.01863386521225E-08" ixy="1.49370815701381E-14" ixz="5.14504997849144E-14" iyy="5.01863212003858E-08" iyz="-1.71620476408047E-14" izz="2.33715865191686E-08"/>
    </inertial>
    <visual>
      <origin rpy="0 0 0" xyz="0 0 0"/>
      <geometry>
        <mesh filename="botyard_hand/meshes/falink2.STL"/>
      </geometry>
      <material name="">
        <color rgba="1 1 1 1"/>
      </material>
    </visual>
    <collision>
      <origin rpy="0 0 0" xyz="0 0 0"/>
      <geometry>
        <mesh filename="botyard_hand/meshes/falink2.STL"/>
      </geometry>
    </collision>
  </link>
  <!-- 使用 prefix 参数为关节命名 -->
  <joint name="FAJ3" type="revolute">
    <origin rpy="0 0 1.5708" xyz="0 0.028001 0.1905"/>
    <!-- 使用 prefix 参数为父连杆命名 -->
    <parent link="fabase"/>
    <!-- 使用 prefix 参数为子连杆命名 -->
    <child link="falink2"/>
    <axis xyz="1 0 0"/>
    <limit acceleration="2.0" effort="0.1" lower="-0.5235" upper="0.5235" velocity="2.0"/>
  </joint>
  <!-- 使用 prefix 参数为连杆命名 -->
  <link name="falink1">
    <inertial>
      <origin rpy="0 0 0" xyz="0.000716824630949655 -0.00609542828247423 0.0212910082526262"/>
      <mass value="0.00472896842585646"/>
      <inertia ixx="6.54620610890924E-07" ixy="-4.59836910833344E-09" ixz="-2.31746933177867E-09" iyy="6.07258952527567E-07" iyz="2.13128089899764E-07" izz="2.91836021108035E-07"/>
    </inertial>
    <visual>
      <origin rpy="0 0 0" xyz="0 0 0"/>
      <geometry>
        <mesh filename="botyard_hand/meshes/falink1.STL"/>
      </geometry>
      <material name="">
        <color rgba="1 1 1 1"/>
      </material>
    </visual>
    <collision>
      <origin rpy="0 0 0" xyz="0 0 0"/>
      <geometry>
        <mesh filename="botyard_hand/meshes/falink1.STL"/>
      </geometry>
    </collision>
  </link>
  <!-- 使用 prefix 参数为关节命名 -->
  <joint name="FAJ2" type="fixed">
    <origin rpy="0 0 -1.5708" xyz="0 0 0.011"/>
    <!-- 使用 prefix 参数为父连杆命名 -->
    <parent link="falink2"/>
    <!-- 使用 prefix 参数为子连杆命名 -->
    <child link="falink1"/>
  </joint>
  <!-- 使用 prefix 参数为连杆命名 -->
  <link name="pmbase">
    <inertial>
      <origin rpy="0 0 0" xyz="8.53609692686815E-07 -0.024308776882631 0.00431490414497454"/>
      <mass value="0.00601940125483358"/>
      <inertia ixx="1.1544501152982E-06" ixy="3.47744097896483E-15" ixz="3.94374970071965E-14" iyy="1.62966970781033E-06" iyz="-3.95045587346745E-08" izz="2.68292417958557E-06"/>
    </inertial>
    <visual>
      <origin rpy="0 0 0" xyz="0 0 0"/>
      <geometry>
        <mesh filename="botyard_hand/meshes/pmbase.STL"/>
      </geometry>
      <material name="">
        <color rgba="1 1 1 1"/>
      </material>
    </visual>
    <collision>
      <origin rpy="0 0 0" xyz="0 0 0"/>
      <geometry>
        <mesh filename="botyard_hand/meshes/pmbase.STL"/>
      </geometry>
    </collision>
  </link>
  <!-- 使用 prefix 参数为关节命名 -->
  <joint name="FAJ1" type="revolute">
    <origin rpy="0 0 0" xyz="0 -0.0193 0.039"/>
    <!-- 使用 prefix 参数为父连杆命名 -->
    <parent link="falink1"/>
    <!-- 使用 prefix 参数为子连杆命名 -->
    <child link="pmbase"/>
    <axis xyz="-1 0 0"/>
    <limit acceleration="2.0" effort="0.1" lower="-0.2618" upper="0.5235" velocity="2.0"/>
  </joint>
  <!-- define a joint connect to other part of robot -->
  <joint name="PALM" type="fixed">
    <origin rpy="0 0 0" xyz="0 -0.0193 0.01"/>
    <parent link="pmbase"/>
    <child link="palm"/>
  </joint>
  <!-- pure URDF goes below -->
  <link name="palm">
    <inertial>
      <origin rpy="0 0 0" xyz="0.00467315921354322 -7.47612565492224E-06 0.0411612387388328"/>
      <mass value="0.0289828312541729"/>
      <inertia ixx="1.04474964158207E-05" ixy="1.02450222919575E-10" ixz="-1.80668551272074E-06" iyy="1.71178957503239E-05" iyz="2.35190736196329E-08" izz="8.47407472988603E-06"/>
    </inertial>
    <visual>
      <origin rpy="0 0 0" xyz="0 0 0"/>
      <geometry>
        <mesh filename="botyard_hand/meshes/palm.STL"/>
      </geometry>
      <material name="">
        <color rgba="1 1 1 1"/>
      </material>
    </visual>
    <collision>
      <origin rpy="0 0 0" xyz="0 0 0"/>
      <geometry>
        <mesh filename="botyard_hand/meshes/palm.STL"/>
      </geometry>
    </collision>
  </link>
  <link name="thbase">
    <inertial>
      <origin rpy="0 0 0" xyz="-0.00179428684346725 2.09600788479009E-08 0.00147248530806168"/>
      <mass value="0.00644352672209423"/>
      <inertia ixx="5.42712823895272E-07" ixy="4.57090657604939E-14" ixz="-2.41334457846003E-09" iyy="6.96430068620061E-07" iyz="2.45814092128719E-13" izz="8.14232088259366E-07"/>
    </inertial>
    <visual>
      <origin rpy="0 0 0" xyz="0 0 0"/>
      <geometry>
        <mesh filename="botyard_hand/meshes/thbase.STL"/>
      </geometry>
      <material name="">
        <color rgba="1 1 1 1"/>
      </material>
    </visual>
    <collision>
      <origin rpy="0 0 0" xyz="0 0 0"/>
      <geometry>
        <mesh filename="botyard_hand/meshes/thbase.STL"/>
      </geometry>
    </collision>
  </link>
  <joint name="THJ4" type="revolute">
    <origin rpy="3.14159 -1.5708 0" xyz="0.026851 0.01315 0.038"/>
    <parent link="palm"/>
    <child link="thbase"/>
    <axis xyz="1 0 0"/>
    <limit acceleration="2.0" effort="0.1" lower="0.0" upper="1.5708" velocity="2.0"/>
  </joint>
  <link name="thproximal">
    <inertial>
      <origin rpy="0 0 0" xyz="0.00638369419270039 -8.78508188083445E-06 -0.000318318507908692"/>
      <mass value="0.00874436649921006"/>
      <inertia ixx="3.75939070373561E-07" ixy="-6.07919194575409E-09" ixz="7.50903074913542E-08" iyy="8.31777797638259E-07" iyz="-3.81373430695677E-09" izz="6.69794720992556E-07"/>
    </inertial>
    <visual>
      <origin rpy="0 0 0" xyz="0 0 0"/>
      <geometry>
        <mesh filename="botyard_hand/meshes/thproximal.STL"/>
      </geometry>
      <material name="">
        <color rgba="1 1 1 1"/>
      </material>
    </visual>
    <collision>
      <origin rpy="0 0 0" xyz="0 0 0"/>
      <geometry>
        <mesh filename="botyard_hand/meshes/thproximal.STL"/>
      </geometry>
    </collision>
  </link>
  <joint name="THJ3" type="revolute">
    <origin rpy="-1.5708 -1.5708 -1.5708" xyz="0 0 0.01575"/>
    <parent link="thbase"/>
    <child link="thproximal"/>
    <axis xyz="-1 0 0"/>
    <limit acceleration="2.0" effort="0.1" lower="0.0" upper="0.7854" velocity="2.0"/>
  </joint>
  <link name="thmiddle">
    <inertial>
      <origin rpy="0 0 0" xyz="-0.000696295114692514 0.000275414873780168 0.0255327021512566"/>
      <mass value="0.00591298052561849"/>
      <inertia ixx="1.06964496585371E-06" ixy="4.52496488925683E-09" ixz="-9.43881698085712E-09" iyy="8.9138484793407E-07" iyz="-2.36519713662575E-09" izz="2.4504036267044E-07"/>
    </inertial>
    <visual>
      <origin rpy="0 0 0" xyz="0 0 0"/>
      <geometry>
        <mesh filename="botyard_hand/meshes/thmiddle.STL"/>
      </geometry>
      <material name="">
        <color rgba="1 1 1 1"/>
      </material>
    </visual>
    <collision>
      <origin rpy="0 0 0" xyz="0 0 0"/>
      <geometry>
        <mesh filename="botyard_hand/meshes/thmiddle.STL"/>
      </geometry>
    </collision>
  </link>
  <joint name="THJ2" type="revolute">
    <origin rpy="1.5708 0 1.5708" xyz="0.025 0 0"/>
    <parent link="thproximal"/>
    <child link="thmiddle"/>
    <axis xyz="-1 0 0"/>
    <limit acceleration="2.0" effort="0.1" lower="0.0" upper="1.5708" velocity="2.0"/>
  </joint>
  <link name="thdistal">
    <inertial>
      <origin rpy="0 0 0" xyz="6.64428156433462E-05 -0.00522038889406494 0.0138629509312514"/>
      <mass value="0.0026081529494485"/>
      <inertia ixx="2.4445745986031E-07" ixy="-8.87971073806119E-10" ixz="2.3829151125442E-09" iyy="3.00016476075754E-07" iyz="2.34308014393757E-08" izz="1.03721856739173E-07"/>
    </inertial>
    <visual>
      <origin rpy="0 0 0" xyz="0 0 0"/>
      <geometry>
        <mesh filename="botyard_hand/meshes/thdistal.STL"/>
      </geometry>
      <material name="">
        <color rgba="1 1 1 1"/>
      </material>
    </visual>
    <collision>
      <origin rpy="0 0 0" xyz="0 0 0"/>
      <geometry>
        <mesh filename="botyard_hand/meshes/thdistal.STL"/>
      </geometry>
    </collision>
  </link>
  <joint name="THJ1" type="revolute">
    <origin rpy="0 0 0" xyz="0 0.003 0.045"/>
    <parent link="thmiddle"/>
    <child link="thdistal"/>
    <axis xyz="-1 0 0"/>
    <limit acceleration="2.0" effort="0.1" lower="0.0" upper="1.5708" velocity="2.0"/>
  </joint>
  <link name="thtip">
  </link>
  <joint name="THJ0" type="fixed">
    <origin rpy="0 0 0" xyz="0 -0.0015 0.0297"/>
    <parent link="thdistal"/>
    <child link="thtip"/>
    <axis xyz="0 0 0"/>
  </joint>
  <link name="ffbase">
    <inertial>
      <origin rpy="0 0 0" xyz="-0.00112189286961021 0.000208475541508962 0.00617879877072101"/>
      <mass value="0.00757937353888617"/>
      <inertia ixx="4.40333843672738E-07" ixy="-1.02490543565402E-09" ixz="4.38718638849792E-08" iyy="5.89927525754156E-07" iyz="-3.16407618692666E-09" izz="3.37649595953186E-07"/>
    </inertial>
    <visual>
      <origin rpy="0 0 0" xyz="0 0 0"/>
      <geometry>
        <mesh filename="botyard_hand/meshes/ffbase.STL"/>
      </geometry>
      <material name="">
        <color rgba="1 1 1 1"/>
      </material>
    </visual>
    <collision>
      <origin rpy="0 0 0" xyz="0 0 0"/>
      <geometry>
        <mesh filename="botyard_hand/meshes/ffbase.STL"/>
      </geometry>
    </collision>
  </link>
  <joint name="FFJ4" type="revolute">
    <origin rpy="0 0 1.5708" xyz="0.030504 0.00045 0.0855"/>
    <parent link="palm"/>
    <child link="ffbase"/>
    <axis xyz="1 0 0"/>
    <limit acceleration="2.0" effort="0.1" lower="-0.1309" upper="0.1309" velocity="2.0"/>
  </joint>
  <link name="ffproximal">
    <inertial>
      <origin rpy="0 0 0" xyz="-0.00196718827387735 -0.000248547242294944 0.0263051638016935"/>
      <mass value="0.00551109036052712"/>
      <inertia ixx="1.03795704448418E-06" ixy="9.78527304732066E-09" ixz="-1.65538602717097E-08" iyy="8.70275327312006E-07" iyz="2.11379894396707E-08" izz="2.37607854319465E-07"/>
    </inertial>
    <visual>
      <origin rpy="0 0 0" xyz="0 0 0"/>
      <geometry>
        <mesh filename="botyard_hand/meshes/ffproximal.STL"/>
      </geometry>
      <material name="">
        <color rgba="1 1 1 1"/>
      </material>
    </visual>
    <collision>
      <origin rpy="0 0 0" xyz="0 0 0"/>
      <geometry>
        <mesh filename="botyard_hand/meshes/ffproximal.STL"/>
      </geometry>
    </collision>
  </link>
  <joint name="FFJ3" type="revolute">
    <origin rpy="0 0 -1.5708" xyz="0 0 0.018"/>
    <parent link="ffbase"/>
    <child link="ffproximal"/>
    <axis xyz="-1 0 0"/>
    <limit acceleration="2.0" effort="0.1" lower="0.0" upper="1.5708" velocity="2.0"/>
  </joint>
  <link name="ffmiddle">
    <inertial>
      <origin rpy="0 0 0" xyz="0.000382629545805049 -0.00305057294683708 0.0123468373884281"/>
      <mass value="0.00397399477571205"/>
      <inertia ixx="3.35444191564615E-07" ixy="1.38344669695991E-09" ixz="4.95002685384417E-10" iyy="2.47384897956612E-07" iyz="-2.70391779997592E-09" izz="1.30213703964171E-07"/>
    </inertial>
    <visual>
      <origin rpy="0 0 0" xyz="0 0 0"/>
      <geometry>
        <mesh filename="botyard_hand/meshes/ffmiddle.STL"/>
      </geometry>
      <material name="">
        <color rgba="1 1 1 1"/>
      </material>
    </visual>
    <collision>
      <origin rpy="0 0 0" xyz="0 0 0"/>
      <geometry>
        <mesh filename="botyard_hand/meshes/ffmiddle.STL"/>
      </geometry>
    </collision>
  </link>
  <joint name="FFJ2" type="revolute">
    <origin rpy="0 0 0" xyz="0 0.003 0.045"/>
    <parent link="ffproximal"/>
    <child link="ffmiddle"/>
    <axis xyz="-1 0 0"/>
    <limit acceleration="2.0" effort="0.1" lower="0.0" upper="1.5708" velocity="2.0"/>
  </joint>
  <link name="ffdistal">
    <inertial>
      <origin rpy="0 0 0" xyz="0.00010613110729394 -0.00174210782128108 0.0146517272199787"/>
      <mass value="0.00588197848950502"/>
      <inertia ixx="4.26396352053566E-07" ixy="4.26289208202645E-10" ixz="-4.45633109841644E-09" iyy="4.68862862225653E-07" iyz="3.43678418970898E-08" izz="1.5593360356169E-07"/>
    </inertial>
    <visual>
      <origin rpy="0 0 0" xyz="0 0 0"/>
      <geometry>
        <mesh filename="botyard_hand/meshes/ffdistal.STL"/>
      </geometry>
      <material name="">
        <color rgba="1 1 1 1"/>
      </material>
    </visual>
    <collision>
      <origin rpy="0 0 0" xyz="0 0 0"/>
      <geometry>
        <mesh filename="botyard_hand/meshes/ffdistal.STL"/>
      </geometry>
    </collision>
  </link>
  <joint name="FFJ1" type="revolute">
    <origin rpy="0 0 0" xyz="0 0 0.025"/>
    <parent link="ffmiddle"/>
    <child link="ffdistal"/>
    <axis xyz="-1 0 0"/>
    <limit acceleration="2.0" effort="0.1" lower="0.0" upper="1.5708" velocity="2.0"/>
  </joint>
  <link name="fftip">
  </link>
  <joint name="FFJ0" type="fixed">
    <origin rpy="0 0 0" xyz="0 -0.0023033 0.03281"/>
    <parent link="ffdistal"/>
    <child link="fftip"/>
    <axis xyz="0 0 0"/>
  </joint>
  <link name="mfbase">
    <inertial>
      <origin rpy="0 0 0" xyz="-0.00112189286961018 0.000208475541508975 0.00617879877072106"/>
      <mass value="0.00757937353888616"/>
      <inertia ixx="4.40333843672737E-07" ixy="-1.02490543565387E-09" ixz="4.38718638849789E-08" iyy="5.89927525754155E-07" iyz="-3.16407618692692E-09" izz="3.37649595953185E-07"/>
    </inertial>
    <visual>
      <origin rpy="0 0 0" xyz="0 0 0"/>
      <geometry>
        <mesh filename="botyard_hand/meshes/mfbase.STL"/>
      </geometry>
      <material name="">
        <color rgba="1 1 1 1"/>
      </material>
    </visual>
    <collision>
      <origin rpy="0 0 0" xyz="0 0 0"/>
      <geometry>
        <mesh filename="botyard_hand/meshes/mfbase.STL"/>
      </geometry>
    </collision>
  </link>
  <joint name="MFJ4" type="revolute">
    <origin rpy="0 0 1.5708" xyz="0.0075044 0.00045 0.0905"/>
    <parent link="palm"/>
    <child link="mfbase"/>
    <axis xyz="1 0 0"/>
    <limit acceleration="2.0" effort="0.1" lower="-0.1309" upper="0.1309" velocity="2.0"/>
  </joint>
  <link name="mfproximal">
    <inertial>
      <origin rpy="0 0 0" xyz="-0.00196718827387734 -0.000248547242294942 0.0263051638016935"/>
      <mass value="0.00551109036052712"/>
      <inertia ixx="1.03795704448418E-06" ixy="9.78527304732057E-09" ixz="-1.65538602717095E-08" iyy="8.70275327312005E-07" iyz="2.11379894396709E-08" izz="2.37607854319465E-07"/>
    </inertial>
    <visual>
      <origin rpy="0 0 0" xyz="0 0 0"/>
      <geometry>
        <mesh filename="botyard_hand/meshes/mfproximal.STL"/>
      </geometry>
      <material name="">
        <color rgba="1 1 1 1"/>
      </material>
    </visual>
    <collision>
      <origin rpy="0 0 0" xyz="0 0 0"/>
      <geometry>
        <mesh filename="botyard_hand/meshes/mfproximal.STL"/>
      </geometry>
    </collision>
  </link>
  <joint name="MFJ3" type="revolute">
    <origin rpy="0 0 -1.5708" xyz="0 0 0.018"/>
    <parent link="mfbase"/>
    <child link="mfproximal"/>
    <axis xyz="-1 0 0"/>
    <limit acceleration="2.0" effort="0.1" lower="0.0" upper="1.5708" velocity="2.0"/>
  </joint>
  <link name="mfmiddle">
    <inertial>
      <origin rpy="0 0 0" xyz="0.000382629545805061 -0.00305057294683722 0.0123468373884282"/>
      <mass value="0.00397399477571206"/>
      <inertia ixx="3.35444191564803E-07" ixy="1.38344669695981E-09" ixz="4.95002685384687E-10" iyy="2.47384897956613E-07" iyz="-2.703917799971E-09" izz="1.30213703964359E-07"/>
    </inertial>
    <visual>
      <origin rpy="0 0 0" xyz="0 0 0"/>
      <geometry>
        <mesh filename="botyard_hand/meshes/mfmiddle.STL"/>
      </geometry>
      <material name="">
        <color rgba="1 1 1 1"/>
      </material>
    </visual>
    <collision>
      <origin rpy="0 0 0" xyz="0 0 0"/>
      <geometry>
        <mesh filename="botyard_hand/meshes/mfmiddle.STL"/>
      </geometry>
    </collision>
  </link>
  <joint name="MFJ2" type="revolute">
    <origin rpy="0 0 0" xyz="0 0.003 0.045"/>
    <parent link="mfproximal"/>
    <child link="mfmiddle"/>
    <axis xyz="-1 0 0"/>
    <limit acceleration="2.0" effort="0.1" lower="0.0" upper="1.5708" velocity="2.0"/>
  </joint>
  <link name="mfdistal">
    <inertial>
      <origin rpy="0 0 0" xyz="0.000106134004411035 -0.00174210903101383 0.0146517228171518"/>
      <mass value="0.00588198032947831"/>
      <inertia ixx="4.2639635533418E-07" ixy="4.26298827754549E-10" ixz="-4.45631713308347E-09" iyy="4.68862859926092E-07" iyz="3.43678259360068E-08" izz="1.55933618695065E-07"/>
    </inertial>
    <visual>
      <origin rpy="0 0 0" xyz="0 0 0"/>
      <geometry>
        <mesh filename="botyard_hand/meshes/mfdistal.STL"/>
      </geometry>
      <material name="">
        <color rgba="1 1 1 1"/>
      </material>
    </visual>
    <collision>
      <origin rpy="0 0 0" xyz="0 0 0"/>
      <geometry>
        <mesh filename="botyard_hand/meshes/mfdistal.STL"/>
      </geometry>
    </collision>
  </link>
  <joint name="MFJ1" type="revolute">
    <origin rpy="0 0 0" xyz="0 0 0.025"/>
    <parent link="mfmiddle"/>
    <child link="mfdistal"/>
    <axis xyz="-1 0 0"/>
    <limit acceleration="2.0" effort="0.1" lower="0.0" upper="1.5708" velocity="2.0"/>
  </joint>
  <link name="mftip">
  </link>
  <joint name="MFJ0" type="fixed">
    <origin rpy="0 0 0" xyz="0 -0.0023033 0.03281"/>
    <parent link="mfdistal"/>
    <child link="mftip"/>
    <axis xyz="0 0 0"/>
  </joint>
  <link name="rfbase">
    <inertial>
      <origin rpy="0 0 0" xyz="-0.00112189286961019 0.000208475541508962 0.00617879877072104"/>
      <mass value="0.00757937353888616"/>
      <inertia ixx="4.40333843672737E-07" ixy="-1.02490543565392E-09" ixz="4.38718638849791E-08" iyy="5.89927525754155E-07" iyz="-3.16407618692704E-09" izz="3.37649595953185E-07"/>
    </inertial>
    <visual>
      <origin rpy="0 0 0" xyz="0 0 0"/>
      <geometry>
        <mesh filename="botyard_hand/meshes/rfbase.STL"/>
      </geometry>
      <material name="">
        <color rgba="1 1 1 1"/>
      </material>
    </visual>
    <collision>
      <origin rpy="0 0 0" xyz="0 0 0"/>
      <geometry>
        <mesh filename="botyard_hand/meshes/rfbase.STL"/>
      </geometry>
    </collision>
  </link>
  <joint name="RFJ4" type="revolute">
    <origin rpy="0 0 1.5708" xyz="-0.015496 0.00045 0.0855"/>
    <parent link="palm"/>
    <child link="rfbase"/>
    <axis xyz="1 0 0"/>
    <limit acceleration="2.0" effort="0.1" lower="-0.1309" upper="0.1309" velocity="2.0"/>
  </joint>
  <link name="rfproximal">
    <inertial>
      <origin rpy="0 0 0" xyz="-0.00196718827387735 -0.000248547242294945 0.0263051638016935"/>
      <mass value="0.00551109036052711"/>
      <inertia ixx="1.03795704448418E-06" ixy="9.78527304732063E-09" ixz="-1.65538602717104E-08" iyy="8.70275327312006E-07" iyz="2.11379894396705E-08" izz="2.37607854319463E-07"/>
    </inertial>
    <visual>
      <origin rpy="0 0 0" xyz="0 0 0"/>
      <geometry>
        <mesh filename="botyard_hand/meshes/rfproximal.STL"/>
      </geometry>
      <material name="">
        <color rgba="1 1 1 1"/>
      </material>
    </visual>
    <collision>
      <origin rpy="0 0 0" xyz="0 0 0"/>
      <geometry>
        <mesh filename="botyard_hand/meshes/rfproximal.STL"/>
      </geometry>
    </collision>
  </link>
  <joint name="RFJ3" type="revolute">
    <origin rpy="0 0 -1.5708" xyz="0 0 0.018"/>
    <parent link="rfbase"/>
    <child link="rfproximal"/>
    <axis xyz="-1 0 0"/>
    <limit acceleration="2.0" effort="0.1" lower="0.0" upper="1.5708" velocity="2.0"/>
  </joint>
  <link name="rfmiddle">
    <inertial>
      <origin rpy="0 0 0" xyz="0.000382629545805044 -0.00305057294683722 0.0123468373884282"/>
      <mass value="0.00397399477571206"/>
      <inertia ixx="3.3544419156483E-07" ixy="1.38344669695899E-09" ixz="4.95002685384575E-10" iyy="2.47384897956613E-07" iyz="-2.7039177999714E-09" izz="1.30213703964385E-07"/>
    </inertial>
    <visual>
      <origin rpy="0 0 0" xyz="0 0 0"/>
      <geometry>
        <mesh filename="botyard_hand/meshes/rfmiddle.STL"/>
      </geometry>
      <material name="">
        <color rgba="1 1 1 1"/>
      </material>
    </visual>
    <collision>
      <origin rpy="0 0 0" xyz="0 0 0"/>
      <geometry>
        <mesh filename="botyard_hand/meshes/rfmiddle.STL"/>
      </geometry>
    </collision>
  </link>
  <joint name="RFJ2" type="revolute">
    <origin rpy="0 0 0" xyz="0 0.003 0.045"/>
    <parent link="rfproximal"/>
    <child link="rfmiddle"/>
    <axis xyz="-1 0 0"/>
    <limit acceleration="2.0" effort="0.1" lower="0.0" upper="1.5708" velocity="2.0"/>
  </joint>
  <link name="rfdistal">
    <inertial>
      <origin rpy="0 0 0" xyz="0.000105533826227052 -0.00174245491421043 0.0146518770270997"/>
      <mass value="0.00588145131515303"/>
      <inertia ixx="4.26346619813091E-07" ixy="4.55156716114043E-10" ixz="-4.46484447447954E-09" iyy="4.68820009905352E-07" iyz="3.43579383267477E-08" izz="1.55875343716759E-07"/>
    </inertial>
    <visual>
      <origin rpy="0 0 0" xyz="0 0 0"/>
      <geometry>
        <mesh filename="botyard_hand/meshes/rfdistal.STL"/>
      </geometry>
      <material name="">
        <color rgba="1 1 1 1"/>
      </material>
    </visual>
    <collision>
      <origin rpy="0 0 0" xyz="0 0 0"/>
      <geometry>
        <mesh filename="botyard_hand/meshes/rfdistal.STL"/>
      </geometry>
    </collision>
  </link>
  <joint name="RFJ1" type="revolute">
    <origin rpy="0 0 0" xyz="0 0 0.025"/>
    <parent link="rfmiddle"/>
    <child link="rfdistal"/>
    <axis xyz="-1 0 0"/>
    <limit acceleration="2.0" effort="0.1" lower="0.0" upper="1.5708" velocity="2.0"/>
  </joint>
  <link name="rftip">
  </link>
  <joint name="RFJ0" type="fixed">
    <origin rpy="0 0 0" xyz="0 -0.0023033 0.03281"/>
    <parent link="rfdistal"/>
    <child link="rftip"/>
    <axis xyz="0 0 0"/>
  </joint>
  <link name="lfpalm">
    <inertial>
      <origin rpy="0 0 0" xyz="0.00952070102948792 -0.000716360636126134 0.0177911371602309"/>
      <mass value="0.00678369782170271"/>
      <inertia ixx="4.10675769110166E-07" ixy="3.05378125911323E-08" ixz="-1.43648699262145E-07" iyy="6.84885914107377E-07" iyz="1.21865059132884E-08" izz="5.84455425338444E-07"/>
    </inertial>
    <visual>
      <origin rpy="0 0 0" xyz="0 0 0"/>
      <geometry>
        <mesh filename="botyard_hand/meshes/lfpalm.STL"/>
      </geometry>
      <material name="">
        <color rgba="1 1 1 1"/>
      </material>
    </visual>
    <collision>
      <origin rpy="0 0 0" xyz="0 0 0"/>
      <geometry>
        <mesh filename="botyard_hand/meshes/lfpalm.STL"/>
      </geometry>
    </collision>
  </link>
  <joint name="LFJ5" type="revolute">
    <origin rpy="0 -1.0472 0" xyz="-0.025779 0 0.032848"/>
    <parent link="palm"/>
    <child link="lfpalm"/>
    <axis xyz="-1 0 0"/>
    <limit acceleration="2.0" effort="0.1" lower="0.0" upper="0.1309" velocity="2.0"/>
  </joint>
  <link name="lfbase">
    <inertial>
      <origin rpy="0 0 0" xyz="-0.00112189286961001 0.000208475541513729 0.0061787987707209"/>
      <mass value="0.00757937353888615"/>
      <inertia ixx="4.40333843672739E-07" ixy="-1.02490543562026E-09" ixz="4.38718638849765E-08" iyy="5.89927525754149E-07" iyz="-3.16407618712094E-09" izz="3.37649595953187E-07"/>
    </inertial>
    <visual>
      <origin rpy="0 0 0" xyz="0 0 0"/>
      <geometry>
        <mesh filename="botyard_hand/meshes/lfbase.STL"/>
      </geometry>
      <material name="">
        <color rgba="1 1 1 1"/>
      </material>
    </visual>
    <collision>
      <origin rpy="0 0 0" xyz="0 0 0"/>
      <geometry>
        <mesh filename="botyard_hand/meshes/lfbase.STL"/>
      </geometry>
    </collision>
  </link>
  <joint name="LFJ4" type="revolute">
    <origin rpy="1.0472 0 1.5708" xyz="0.034911 0.00045 0.034839"/>
    <parent link="lfpalm"/>
    <child link="lfbase"/>
    <axis xyz="1 0 0"/>
    <limit acceleration="2.0" effort="0.1" lower="-0.1309" upper="0.1309" velocity="2.0"/>
  </joint>
  <link name="lfproximal">
    <inertial>
      <origin rpy="0 0 0" xyz="-0.00196718827389752 -0.000248547242294942 0.026305163801692"/>
      <mass value="0.00551109036052711"/>
      <inertia ixx="1.0379570444842E-06" ixy="9.78527304730434E-09" ixz="-1.65538602710957E-08" iyy="8.70275327312005E-07" iyz="2.11379894396788E-08" izz="2.37607854319437E-07"/>
    </inertial>
    <visual>
      <origin rpy="0 0 0" xyz="0 0 0"/>
      <geometry>
        <mesh filename="botyard_hand/meshes/lfproximal.STL"/>
      </geometry>
      <material name="">
        <color rgba="1 1 1 1"/>
      </material>
    </visual>
    <collision>
      <origin rpy="0 0 0" xyz="0 0 0"/>
      <geometry>
        <mesh filename="botyard_hand/meshes/lfproximal.STL"/>
      </geometry>
    </collision>
  </link>
  <joint name="LFJ3" type="revolute">
    <origin rpy="0 0 -1.5708" xyz="0 0 0.018"/>
    <parent link="lfbase"/>
    <child link="lfproximal"/>
    <axis xyz="-1 0 0"/>
    <limit acceleration="2.0" effort="0.1" lower="0.0" upper="1.5708" velocity="2.0"/>
  </joint>
  <link name="lfmiddle">
    <inertial>
      <origin rpy="0 0 0" xyz="0.000382629545795585 -0.00305057294683723 0.0123468373884285"/>
      <mass value="0.00397399477571205"/>
      <inertia ixx="3.35444191564547E-07" ixy="1.38344669696349E-09" ixz="4.95002685542594E-10" iyy="2.47384897956285E-07" iyz="-2.70391779997448E-09" izz="1.30213703964431E-07"/>
    </inertial>
    <visual>
      <origin rpy="0 0 0" xyz="0 0 0"/>
      <geometry>
        <mesh filename="botyard_hand/meshes/lfmiddle.STL"/>
      </geometry>
      <material name="">
        <color rgba="1 1 1 1"/>
      </material>
    </visual>
    <collision>
      <origin rpy="0 0 0" xyz="0 0 0"/>
      <geometry>
        <mesh filename="botyard_hand/meshes/lfmiddle.STL"/>
      </geometry>
    </collision>
  </link>
  <joint name="LFJ2" type="revolute">
    <origin rpy="0 0 0" xyz="0 0.003 0.045"/>
    <parent link="lfproximal"/>
    <child link="lfmiddle"/>
    <axis xyz="-1 0 0"/>
    <limit acceleration="2.0" effort="0.1" lower="0.0" upper="1.5708" velocity="2.0"/>
  </joint>
  <link name="lfdistal">
    <inertial>
      <origin rpy="0 0 0" xyz="0.000105517467005448 -0.00174246287824984 0.0146518725605457"/>
      <mass value="0.00588144497831721"/>
      <inertia ixx="4.26347396534589E-07" ixy="4.55104706366137E-10" ixz="-4.4640805732829E-09" iyy="4.68819653775823E-07" iyz="3.43585680004646E-08" izz="1.55874900663911E-07"/>
    </inertial>
    <visual>
      <origin rpy="0 0 0" xyz="0 0 0"/>
      <geometry>
        <mesh filename="botyard_hand/meshes/lfdistal.STL"/>
      </geometry>
      <material name="">
        <color rgba="1 1 1 1"/>
      </material>
    </visual>
    <collision>
      <origin rpy="0 0 0" xyz="0 0 0"/>
      <geometry>
        <mesh filename="botyard_hand/meshes/lfdistal.STL"/>
      </geometry>
    </collision>
  </link>
  <joint name="LFJ1" type="revolute">
    <origin rpy="0 0 0" xyz="0 0 0.025"/>
    <parent link="lfmiddle"/>
    <child link="lfdistal"/>
    <axis xyz="-1 0 0"/>
    <limit acceleration="2.0" effort="0.1" lower="0.0" upper="1.5708" velocity="2.0"/>
  </joint>
  <link name="lftip">
  </link>
  <joint name="LFJ0" type="fixed">
    <origin rpy="0 0 0" xyz="0 -0.0023033 0.03281"/>
    <parent link="lfdistal"/>
    <child link="lftip"/>
    <axis xyz="0 0 0"/>
  </joint>
  <link name="central">
  </link>
  <joint name="CJ0" type="fixed">
    <origin rpy="0 0 0" xyz="0 0.01265 0.045"/>
    <parent link="palm"/>
    <child link="central"/>
    <axis xyz="0 0 0"/>
  </joint>
  <!-- construct pure URDF end -->
  <!-- real <ros2_control> tag starts here -->
  <ros2_control name="dexhand" type="system">
    <hardware>
      <!-- 连接真机通信 -->
      <plugin>dexhand_hardware_interface/DexhandHardwareInterface</plugin>
      <param name="port_name">/dev/dexhand</param>
      <param name="hand_id">0</param>
      <param name="baudrate">115200</param>
      <param name="timeout_ms">200</param>
    </hardware>
    <joint name="FAJ1">
      <command_interface name="position">
        <param name="min">-0.2618</param>
        <param name="max">0.5235</param>
      </command_interface>
      <command_interface name="velocity">
        <param name="min">0.0</param>
        <param name="max">2.0</param>
      </command_interface>
      <!-- <command_interface name="effort"/>-->
      <state_interface name="position">
        <param name="initial_value">0</param>
      </state_interface>
      <state_interface name="velocity">
        <param name="initial_value">0.0</param>
      </state_interface>
      <!-- <state_interface name="effort"/>-->
    </joint>
    <joint name="FAJ3">
      <command_interface name="position">
        <param name="min">-0.5235</param>
        <param name="max">0.5235</param>
      </command_interface>
      <command_interface name="velocity">
        <param name="min">0.0</param>
        <param name="max">2.0</param>
      </command_interface>
      <!-- <command_interface name="effort"/>-->
      <state_interface name="position">
        <param name="initial_value">0</param>
      </state_interface>
      <state_interface name="velocity">
        <param name="initial_value">0.0</param>
      </state_interface>
      <!-- <state_interface name="effort"/>-->
    </joint>
    <joint name="FFJ1">
      <command_interface name="position">
        <param name="min">0.0</param>
        <param name="max">1.5708</param>
      </command_interface>
      <command_interface name="velocity">
        <param name="min">0.0</param>
        <param name="max">2.0</param>
      </command_interface>
      <!-- <command_interface name="effort"/>-->
      <state_interface name="position">
        <param name="initial_value">0</param>
      </state_interface>
      <state_interface name="velocity">
        <param name="initial_value">0.0</param>
      </state_interface>
      <!-- <state_interface name="effort"/>-->
    </joint>
    <joint name="FFJ2">
      <command_interface name="position">
        <param name="min">0.0</param>
        <param name="max">1.5708</param>
      </command_interface>
      <command_interface name="velocity">
        <param name="min">0.0</param>
        <param name="max">2.0</param>
      </command_interface>
      <!-- <command_interface name="effort"/>-->
      <state_interface name="position">
        <param name="initial_value">0</param>
      </state_interface>
      <state_interface name="velocity">
        <param name="initial_value">0.0</param>
      </state_interface>
      <!-- <state_interface name="effort"/>-->
    </joint>
    <joint name="FFJ3">
      <command_interface name="position">
        <param name="min">0.0</param>
        <param name="max">1.5708</param>
      </command_interface>
      <command_interface name="velocity">
        <param name="min">0.0</param>
        <param name="max">2.0</param>
      </command_interface>
      <!-- <command_interface name="effort"/>-->
      <state_interface name="position">
        <param name="initial_value">0</param>
      </state_interface>
      <state_interface name="velocity">
        <param name="initial_value">0.0</param>
      </state_interface>
      <!-- <state_interface name="effort"/>-->
    </joint>
    <joint name="FFJ4">
      <command_interface name="position">
        <param name="min">-0.1309</param>
        <param name="max">0.1309</param>
      </command_interface>
      <command_interface name="velocity">
        <param name="min">0.0</param>
        <param name="max">2.0</param>
      </command_interface>
      <!-- <command_interface name="effort"/>-->
      <state_interface name="position">
        <param name="initial_value">0</param>
      </state_interface>
      <state_interface name="velocity">
        <param name="initial_value">0.0</param>
      </state_interface>
      <!-- <state_interface name="effort"/>-->
    </joint>
    <joint name="LFJ1">
      <command_interface name="position">
        <param name="min">0.0</param>
        <param name="max">1.5708</param>
      </command_interface>
      <command_interface name="velocity">
        <param name="min">0.0</param>
        <param name="max">2.0</param>
      </command_interface>
      <!-- <command_interface name="effort"/>-->
      <state_interface name="position">
        <param name="initial_value">0</param>
      </state_interface>
      <state_interface name="velocity">
        <param name="initial_value">0.0</param>
      </state_interface>
      <!-- <state_interface name="effort"/>-->
    </joint>
    <joint name="LFJ2">
      <command_interface name="position">
        <param name="min">0.0</param>
        <param name="max">1.5708</param>
      </command_interface>
      <command_interface name="velocity">
        <param name="min">0.0</param>
        <param name="max">2.0</param>
      </command_interface>
      <!-- <command_interface name="effort"/>-->
      <state_interface name="position">
        <param name="initial_value">0</param>
      </state_interface>
      <state_interface name="velocity">
        <param name="initial_value">0.0</param>
      </state_interface>
      <!-- <state_interface name="effort"/>-->
    </joint>
    <joint name="LFJ3">
      <command_interface name="position">
        <param name="min">0.0</param>
        <param name="max">1.5708</param>
      </command_interface>
      <command_interface name="velocity">
        <param name="min">0.0</param>
        <param name="max">2.0</param>
      </command_interface>
      <!-- <command_interface name="effort"/>-->
      <state_interface name="position">
        <param name="initial_value">0</param>
      </state_interface>
      <state_interface name="velocity">
        <param name="initial_value">0.0</param>
      </state_interface>
      <!-- <state_interface name="effort"/>-->
    </joint>
    <joint name="LFJ4">
      <command_interface name="position">
        <param name="min">-0.2616</param>
        <param name="max">0.2616</param>
      </command_interface>
      <command_interface name="velocity">
        <param name="min">0.0</param>
        <param name="max">2.0</param>
      </command_interface>
      <!-- <command_interface name="effort"/>-->
      <state_interface name="position">
        <param name="initial_value">0</param>
      </state_interface>
      <state_interface name="velocity">
        <param name="initial_value">0.0</param>
      </state_interface>
      <!-- <state_interface name="effort"/>-->
    </joint>
    <joint name="LFJ5">
      <command_interface name="position">
        <param name="min">0.0</param>
        <param name="max">1.5708</param>
      </command_interface>
      <command_interface name="velocity">
        <param name="min">0.0</param>
        <param name="max">2.0</param>
      </command_interface>
      <!-- <command_interface name="effort"/>-->
      <state_interface name="position">
        <param name="initial_value">0</param>
      </state_interface>
      <state_interface name="velocity">
        <param name="initial_value">0.0</param>
      </state_interface>
      <!-- <state_interface name="effort"/>-->
    </joint>
    <joint name="MFJ1">
      <command_interface name="position">
        <param name="min">0.0</param>
        <param name="max">1.5708</param>
      </command_interface>
      <command_interface name="velocity">
        <param name="min">0.0</param>
        <param name="max">2.0</param>
      </command_interface>
      <!-- <command_interface name="effort"/>-->
      <state_interface name="position">
        <param name="initial_value">0</param>
      </state_interface>
      <state_interface name="velocity">
        <param name="initial_value">0.0</param>
      </state_interface>
      <!-- <state_interface name="effort"/>-->
    </joint>
    <joint name="MFJ2">
      <command_interface name="position">
        <param name="min">0.0</param>
        <param name="max">1.5708</param>
      </command_interface>
      <command_interface name="velocity">
        <param name="min">0.0</param>
        <param name="max">2.0</param>
      </command_interface>
      <!-- <command_interface name="effort"/>-->
      <state_interface name="position">
        <param name="initial_value">0</param>
      </state_interface>
      <state_interface name="velocity">
        <param name="initial_value">0.0</param>
      </state_interface>
      <!-- <state_interface name="effort"/>-->
    </joint>
    <joint name="MFJ3">
      <command_interface name="position">
        <param name="min">0.0</param>
        <param name="max">1.5708</param>
      </command_interface>
      <command_interface name="velocity">
        <param name="min">0.0</param>
        <param name="max">2.0</param>
      </command_interface>
      <!-- <command_interface name="effort"/>-->
      <state_interface name="position">
        <param name="initial_value">0</param>
      </state_interface>
      <state_interface name="velocity">
        <param name="initial_value">0.0</param>
      </state_interface>
      <!-- <state_interface name="effort"/>-->
    </joint>
    <joint name="MFJ4">
      <command_interface name="position">
        <param name="min">-0.2616</param>
        <param name="max">0.2616</param>
      </command_interface>
      <command_interface name="velocity">
        <param name="min">0.0</param>
        <param name="max">2.0</param>
      </command_interface>
      <!-- <command_interface name="effort"/>-->
      <state_interface name="position">
        <param name="initial_value">0</param>
      </state_interface>
      <state_interface name="velocity">
        <param name="initial_value">0.0</param>
      </state_interface>
      <!-- <state_interface name="effort"/>-->
    </joint>
    <joint name="RFJ1">
      <command_interface name="position">
        <param name="min">0.0</param>
        <param name="max">1.5708</param>
      </command_interface>
      <command_interface name="velocity">
        <param name="min">0.0</param>
        <param name="max">2.0</param>
      </command_interface>
      <!-- <command_interface name="effort"/>-->
      <state_interface name="position">
        <param name="initial_value">0</param>
      </state_interface>
      <state_interface name="velocity">
        <param name="initial_value">0.0</param>
      </state_interface>
      <!-- <state_interface name="effort"/>-->
    </joint>
    <joint name="RFJ2">
      <command_interface name="position">
        <param name="min">0.0</param>
        <param name="max">1.5708</param>
      </command_interface>
      <command_interface name="velocity">
        <param name="min">0.0</param>
        <param name="max">2.0</param>
      </command_interface>
      <!-- <command_interface name="effort"/>-->
      <state_interface name="position">
        <param name="initial_value">0</param>
      </state_interface>
      <state_interface name="velocity">
        <param name="initial_value">0.0</param>
      </state_interface>
      <!-- <state_interface name="effort"/>-->
    </joint>
    <joint name="RFJ3">
      <command_interface name="position">
        <param name="min">0.0</param>
        <param name="max">1.5708</param>
      </command_interface>
      <command_interface name="velocity">
        <param name="min">0.0</param>
        <param name="max">2.0</param>
      </command_interface>
      <!-- <command_interface name="effort"/>-->
      <state_interface name="position">
        <param name="initial_value">0</param>
      </state_interface>
      <state_interface name="velocity">
        <param name="initial_value">0.0</param>
      </state_interface>
      <!-- <state_interface name="effort"/>-->
    </joint>
    <joint name="RFJ4">
      <command_interface name="position">
        <param name="min">-0.2616</param>
        <param name="max">0.2616</param>
      </command_interface>
      <command_interface name="velocity">
        <param name="min">0.0</param>
        <param name="max">2.0</param>
      </command_interface>
      <!-- <command_interface name="effort"/>-->
      <state_interface name="position">
        <param name="initial_value">0</param>
      </state_interface>
      <state_interface name="velocity">
        <param name="initial_value">0.0</param>
      </state_interface>
      <!-- <state_interface name="effort"/>-->
    </joint>
    <joint name="THJ1">
      <command_interface name="position">
        <param name="min">0.0</param>
        <param name="max">1.5708</param>
      </command_interface>
      <command_interface name="velocity">
        <param name="min">0.0</param>
        <param name="max">2.0</param>
      </command_interface>
      <!-- <command_interface name="effort"/>-->
      <state_interface name="position">
        <param name="initial_value">0</param>
      </state_interface>
      <state_interface name="velocity">
        <param name="initial_value">0.0</param>
      </state_interface>
      <!-- <state_interface name="effort"/>-->
    </joint>
    <joint name="THJ2">
      <command_interface name="position">
        <param name="min">0.0</param>
        <param name="max">1.5708</param>
      </command_interface>
      <command_interface name="velocity">
        <param name="min">0.0</param>
        <param name="max">2.0</param>
      </command_interface>
      <!-- <command_interface name="effort"/>-->
      <state_interface name="position">
        <param name="initial_value">0</param>
      </state_interface>
      <state_interface name="velocity">
        <param name="initial_value">0.0</param>
      </state_interface>
      <!-- <state_interface name="effort"/>-->
    </joint>
    <joint name="THJ3">
      <command_interface name="position">
        <param name="min">0.0</param>
        <param name="max">0.7854</param>
      </command_interface>
      <command_interface name="velocity">
        <param name="min">0.0</param>
        <param name="max">2.0</param>
      </command_interface>
      <!-- <command_interface name="effort"/>-->
      <state_interface name="position">
        <param name="initial_value">0</param>
      </state_interface>
      <state_interface name="velocity">
        <param name="initial_value">0.0</param>
      </state_interface>
      <!-- <state_interface name="effort"/>-->
    </joint>
    <joint name="THJ4">
      <command_interface name="position">
        <param name="min">-0.08</param>
        <param name="max">1.5708</param>
      </command_interface>
      <command_interface name="velocity">
        <param name="min">0.0</param>
        <param name="max">2.0</param>
      </command_interface>
      <!-- <command_interface name="effort"/>-->
      <state_interface name="position">
        <param name="initial_value">0</param>
      </state_interface>
      <state_interface name="velocity">
        <param name="initial_value">0.0</param>
      </state_interface>
      <!-- <state_interface name="effort"/>-->
    </joint>
  </ros2_control>
  <!-- 手部碰撞球 -->
  <!-- 碰撞球考虑到手部可能抓握了物品，对灵巧手额外增加碰撞体积 -->
  <link name="dexhand_collision_sphere">
    <visual name="">
      <origin rpy="0.0 0.0 0.0" xyz="0.0 0.0 0.0"/>
      <geometry>
        <sphere radius="0.1"/>
      </geometry>
      <material name="">
        <color rgba="1.0 0.0 0.0 1.0"/>
        <texture filename=""/>
      </material>
    </visual>
    <collision>
      <origin rpy="0.0 0.0 0.0" xyz="0.0 0.0 0.0"/>
      <geometry>
        <sphere radius="0.1"/>
      </geometry>
    </collision>
  </link>
  <joint name="dexhand_collision_sphere_joint" type="fixed">
    <origin rpy="0.0 0.0 0.0" xyz="0.0 0.05 0.35"/>
    <parent link="fabase"/>
    <child link="dexhand_collision_sphere"/>
  </joint>
  <!-- Grasp Center -->
  <link name="tcp"/>
  <joint name="tcp_joint" type="fixed">
    <origin rpy="0 0 3.141592653589793" xyz="0 0 0.3"/>
    <parent link="tool0"/>
    <child link="tcp"/>
  </joint>
</robot>

